Workbook

Sheet GFNORTEO
A1: Fecha | B1: Precio | C1: Rend. (Día) | D1: Rend. (Ln) | F1: Precio.Act | G1: =B2 -> 168.52
A2: 30.04.2025 | B2: 168.52 | C2: =(B2/B3)-1 -> 0.019294744 | D2: =LN(B2/B3) -> 0.019110961 | F2: Min | G2: =MIN(B2:B1260) -> 65.91
A3: 29.04.2025 | B3: 165.33 | C3: =(B3/B4)-1 -> -0.011184211 | D3: =LN(B3/B4) -> -0.011247224 | F3: Max | G3: =MAX(B2:B1260) -> 189.85
A4: 28.04.2025 | B4: 167.2 | C4: =(B4/B5)-1 -> 0.021068702 | D4: =LN(B4/B5) -> 0.020849826 | F4: Prom | G4: =AVERAGE(B2:B1260) -> 134.3214
A5: 25.04.2025 | B5: 163.75 | C5: =(B5/B6)-1 -> 0.017839383 | D5: =LN(B5/B6) -> 0.017682129 | F5: Desv. | G5: =STDEVA(B2:B1260) -> 25.490303
A6: 24.04.2025 | B6: 160.88 | C6: =(B6/B7)-1 -> 0.0068214532 | D6: =LN(B6/B7) -> 0.0067982923
A7: 23.04.2025 | B7: 159.79 | C7: =(B7/B8)-1 -> 0.016088007 | D7: =LN(B7/B8) -> 0.015959967
A8: 22.04.2025 | B8: 157.26 | C8: =(B8/B9)-1 -> 0.044708696 | D8: =LN(B8/B9) -> 0.043738087 | F8: RENDIMIENTO | G8: Diario | H8: Ln
A9: 21.04.2025 | B9: 150.53 | C9: =(B9/B10)-1 -> 0.022552816 | D9: =LN(B9/B10) -> 0.022302261 | F9: Min | G9: =MIN(C2:C1259) -> -0.11135899 | H9: =MIN(D2:D1259) -> -0.11806194
A10: 16.04.2025 | B10: 147.21 | C10: =(B10/B11)-1 -> -0.0056737589 | D10: =LN(B10/B11) -> -0.0056899158 | F10: Max | G10: =MAX(C2:C1259) -> 0.088737695 | H10: =MAX(D2:D1259) -> 0.085018948
A11: 15.04.2025 | B11: 148.05 | C11: =(B11/B12)-1 -> 0.021175335 | D11: =LN(B11/B12) -> 0.020954253 | F11: Prom (Rendimiento Esperado) | G11: =SUM(C2:C1259)/1259 -> 0.00098576928 | H11: =AVERAGE(C2:C1259) -> 0.00098655288
A12: 14.04.2025 | B12: 144.98 | C12: =(B12/B13)-1 -> 0.023725463 | D12: =LN(B12/B13) -> 0.023448388 | F12: Prom Anual | G12: =G11*252 -> 0.24841386 | H12: =H11*252 -> 0.24861133 | J12: Se consideran los daños de 252 días
A13: 11.04.2025 | B13: 141.62 | C13: =(B13/B14)-1 -> -0.02458847 | D13: =LN(B13/B14) -> -0.024895815 | F13: Desv. | G13: =STDEVA(C2:C1256) -> 0.021949827 | H13: =STDEVA(D2:D1256) -> 0.021920089
A14: 10.04.2025 | B14: 145.19 | C14: =(B14/B15)-1 -> -0.034769313 | D14: =LN(B14/B15) -> -0.035388152 | F14: Desv. Anual | G14: =G13*SQRT(252) -> 0.3484427 | H14: =H13*SQRT(252) -> 0.34797063 | J14: Se considera la raíz de 252
A15: 09.04.2025 | B15: 150.42 | C15: =(B15/B16)-1 -> 0.088737695 | D15: =LN(B15/B16) -> 0.085018948 | F15: Varianza | G15: =VARA(C2:C1259) -> 0.00048130731 | H15: =VARA(D2:D1259) -> 0.00048000351
A16: 08.04.2025 | B16: 138.16 | C16: =(B16/B17)-1 -> 0.015882353 | D16: =LN(B16/B17) -> 0.015757548 | F16: Volatilidad | G16: =SQRT(G15) -> 0.021938717 | H16: =SQRT(H15) -> 0.021908982
A17: 07.04.2025 | B17: 136 | C17: =(B17/B18)-1 -> -0.055096227 | D17: =LN(B17/B18) -> -0.056672185
A18: 04.04.2025 | B18: 143.93 | C18: =(B18/B19)-1 -> -0.067871252 | D18: =LN(B18/B19) -> -0.070284332
A19: 03.04.2025 | B19: 154.41 | C19: =(B19/B20)-1 -> 0.064823116 | D19: =LN(B19/B20) -> 0.062808697
A20: 02.04.2025 | B20: 145.01 | C20: =(B20/B21)-1 -> 0.0040853067 | D20: =LN(B20/B21) -> 0.0040769845
A21: 01.04.2025 | B21: 144.42 | C21: =(B21/B22)-1 -> 0.01754386 | D21: =LN(B21/B22) -> 0.017391743
A22: 31.03.2025 | B22: 141.93 | C22: =(B22/B23)-1 -> -0.027277089 | D22: =LN(B22/B23) -> -0.027656015
A23: 28.03.2025 | B23: 145.91 | C23: =(B23/B24)-1 -> -0.0095037676 | D23: =LN(B23/B24) -> -0.0095492166
A24: 27.03.2025 | B24: 147.31 | C24: =(B24/B25)-1 -> 0.02078858 | D24: =LN(B24/B25) -> 0.020575446
A25: 26.03.2025 | B25: 144.31 | C25: =(B25/B26)-1 -> -0.023348674 | D25: =LN(B25/B26) -> -0.023625572
A26: 25.03.2025 | B26: 147.76 | C26: =(B26/B27)-1 -> -0.010778603 | D26: =LN(B26/B27) -> -0.010837113
A27: 24.03.2025 | B27: 149.37 | C27: =(B27/B28)-1 -> -0.010860208 | D27: =LN(B27/B28) -> -0.01091961
A28: 21.03.2025 | B28: 151.01 | C28: =(B28/B29)-1 -> 0.0045902076 | D28: =LN(B28/B29) -> 0.0045797047
... A1260: 30.04.2020 | B1260: 65.91 | C1260: =(B1260/B1261)-1 -> #DIV/0! | D1260: =LN(B1260/B1261) -> #DIV/0!

Sheet KOFUBL
A1: Fecha | B1: Precio | C1: Rend. (Día) | D1: Rend. (Ln) | F1: Precio.Act | G1: =B2 -> 184.71
A2: 30.04.2025 | B2: 184.71 | C2: =(B2/B3)-1 -> 0.017798104 | D2: =LN(B2/B3) -> 0.017641573 | F2: Min | G2: =MIN(B2:B1260) -> 77.3
A3: 29.04.2025 | B3: 181.48 | C3: =(B3/B4)-1 -> -0.035860384 | D3: =LN(B3/B4) -> -0.036519165 | F3: Max | G3: =MAX(B2:B1260) -> 194.88
A4: 28.04.2025 | B4: 188.23 | C4: =(B4/B5)-1 -> -0.018049977 | D4: =LN(B4/B5) -> -0.018214865 | F4: Prom | G4: =AVERAGE(B2:B1260) -> 129.43798
A5: 25.04.2025 | B5: 191.69 | C5: =(B5/B6)-1 -> -0.0079184349 | D5: =LN(B5/B6) -> -0.0079499522 | F5: Desv. | G5: =STDEVA(B2:B1260) -> 28.506701
A6: 24.04.2025 | B6: 193.22 | C6: =(B6/B7)-1 -> 0.0039488725 | D6: =LN(B6/B7) -> 0.0039410962
A7: 23.04.2025 | B7: 192.46 | C7: =(B7/B8)-1 -> 0.013267348 | D7: =LN(B7/B8) -> 0.013180107
A8: 22.04.2025 | B8: 189.94 | C8: =(B8/B9)-1 -> -0.0035673067 | D8: =LN(B8/B9) -> -0.0035736847 | F8: RENDIMIENTO | G8: Diario | H8: Ln
A9: 21.04.2025 | B9: 190.62 | C9: =(B9/B10)-1 -> 0.0079847708 | D9: =LN(B9/B10) -> 0.0079530612 | F9: Min | G9: =MIN(C2:C1259) -> -0.066650567 | H9: =MIN(D2:D1259) -> -0.068975623
A10: 16.04.2025 | B10: 189.11 | C10: =(B10/B11)-1 -> -0.0094804106 | D10: =LN(B10/B11) -> -0.0095256358 | F10: Max | G10: =MAX(C2:C1259) -> 0.053220785 | H10: =MAX(D2:D1256) -> 0.051852884
A11: 15.04.2025 | B11: 190.92 | C11: =(B11/B12)-1 -> 0.0078657024 | D11: =LN(B11/B12) -> 0.007834929 | F11: Prom (Rendimiento Esperado) | G11: =AVERAGE(C2:C1259) -> 0.00061998579 | H11: =AVERAGE(D2:D1259) -> 0.00051116507
A12: 14.04.2025 | B12: 189.43 | C12: =(B12/B13)-1 -> -5.2787162e-05 | D12: =LN(B12/B13) -> -5.2788555e-05 | F12: Prom Anual | G12: =G11*252 -> 0.15623642 | H12: =H11*252 -> 0.1288136
A13: 11.04.2025 | B13: 189.44 | C13: =(B13/B14)-1 -> -0.018750647 | D13: =LN(B13/B14) -> -0.01892867 | F13: Desv. | G13: =STDEVA(C2:C1259) -> 0.014761337 | H13: =STDEVA(D2:D1259) -> 0.014742742
A14: 10.04.2025 | B14: 193.06 | C14: =(B14/B15)-1 -> 0.00025905394 | D14: =LN(B14/B15) -> 0.00025902039 | F14: Desv. Anual | G14: =G13*SQRT(252) -> 0.23432897 | H14: =H13*SQRT(252) -> 0.23403377
A15: 09.04.2025 | B15: 193.01 | C15: =(B15/B16)-1 -> 0.037911379 | D15: =LN(B15/B16) -> 0.037210404 | F15: Varianza | G15: =VARA(C2:C1259) -> 0.00021789708 | H15: =VARA(D2:D1259) -> 0.00021734844
A16: 08.04.2025 | B16: 185.96 | C16: =(B16/B17)-1 -> -0.0016106518 | D16: =LN(B16/B17) -> -0.0016119503 | F16: Volatilidad | G16: =SQRT(G15) -> 0.014761337 | H16: =SQRT(H15) -> 0.014742742
A17: 07.04.2025 | B17: 186.26 | C17: =(B17/B18)-1 -> -0.024254806 | D17: =LN(B17/B18) -> -0.024553799
A18: 04.04.2025 | B18: 190.89 | C18: =(B18/B19)-1 -> -0.01200766 | D18: =LN(B18/B19) -> -0.012080334
A19: 03.04.2025 | B19: 193.21 | C19: =(B19/B20)-1 -> -0.008569376 | D19: =LN(B19/B20) -> -0.0086063042
A20: 02.04.2025 | B20: 194.88 | C20: =(B20/B21)-1 -> 0.02047442 | D20: =LN(B20/B21) -> 0.020267637
A21: 01.04.2025 | B21: 190.97 | C21: =(B21/B22)-1 -> 0.020902384 | D21: =LN(B21/B22) -> 0.020686927
A22: 31.03.2025 | B22: 187.06 | C22: =(B22/B23)-1 -> -0.0087435748 | D22: =LN(B22/B23) -> -0.0087820241
A23: 28.03.2025 | B23: 188.71 | C23: =(B23/B24)-1 -> 0.015388754 | D23: =LN(B23/B24) -> 0.015271548
A24: 27.03.2025 | B24: 185.85 | C24: =(B24/B25)-1 -> 0.014742015 | D24: =LN(B24/B25) -> 0.014634408
A25: 26.03.2025 | B25: 183.15 | C25: =(B25/B26)-1 -> 0.016709226 | D25: =LN(B25/B26) -> 0.016571163
A26: 25.03.2025 | B26: 180.14 | C26: =(B26/B27)-1 -> 0.0200453 | D26: =LN(B26/B27) -> 0.019847038
A27: 24.03.2025 | B27: 176.6 | C27: =(B27/B28)-1 -> -0.011972698 | D27: =LN(B27/B28) -> -0.012044948
A28: 21.03.2025 | B28: 178.74 | C28: =(B28/B29)-1 -> -0.023865436 | D28: =LN(B28/B29) -> -0.024154829
... A1260: 30.04.2020 | B1260: 97.1 | C1260: =(B1260/B1261)-1 -> #DIV/0! | D1260: =LN(B1260/B1261) -> #DIV/0!

Sheet TLEVISACPO
A1: Fecha | B1: Precio | C1: Rend. (Día) | D1: Rend. (Ln) | F1: Precio.Act | G1: =B2 -> 7.14
A2: 30.04.2025 | B2: 7.14 | C2: =(B2/B3)-1 -> -0.013812155 | D2: =LN(B2/B3) -> -0.01390843 | F2: Min | G2: =MIN(B2:B1260) -> 6.62
A3: 29.04.2025 | B3: 7.24 | C3: =(B3/B4)-1 -> -0.065806452 | D3: =LN(B3/B4) -> -0.068071637 | F3: Max | G3: =MAX(B2:B1260) -> 59.59
A4: 28.04.2025 | B4: 7.75 | C4: =(B4/B5)-1 -> -0.0064102564 | D4: =LN(B4/B5) -> -0.0064308903 | F4: Prom | G4: =AVERAGE(B2:B1260) -> 24.473519
A5: 25.04.2025 | B5: 7.8 | C5: =(B5/B6)-1 -> 0.027667984 | D5: =LN(B5/B6) -> 0.027292142 | F5: Desv. | G5: =STDEVA(B2:B1260) -> 14.626228
A6: 24.04.2025 | B6: 7.59 | C6: =(B6/B7)-1 -> -0.0078431373 | D6: =LN(B6/B7) -> -0.0078740564
A7: 23.04.2025 | B7: 7.65 | C7: =(B7/B8)-1 -> 0.046511628 | D7: =LN(B7/B8) -> 0.045462374
A8: 22.04.2025 | B8: 7.31 | C8: =(B8/B9)-1 -> 0.016689847 | D8: =LN(B8/B9) -> 0.016552102 | F8: RENDIMIENTO | G8: Diario | H8: Ln
A9: 21.04.2025 | B9: 7.19 | C9: =(B9/B10)-1 -> 0.021306818 | D9: =LN(B9/B10) -> 0.021083002 | F9: Min | G9: =MIN(C2:C1259) -> -0.10045203 | H9: =MIN(D2:D1259) -> -0.1058629
A10: 16.04.2025 | B10: 7.04 | C10: =(B10/B11)-1 -> 0.010043042 | D10: =LN(B10/B11) -> 0.0099929454 | F10: Max | G10: =MAX(C2:C1259) -> 0.22848008 | H10: =MAX(D2:D1259) -> 0.2057777
A11: 15.04.2025 | B11: 6.97 | C11: =(B11/B12)-1 -> 0.01161103 | D11: =LN(B11/B12) -> 0.01154414 | F11: Prom (Rendimiento Esperado) | G11: =AVERAGE(C2:C1259) -> -0.00063173613 | H11: =AVERAGE(D2:D1259) -> -0.0010153181
A12: 14.04.2025 | B12: 6.89 | C12: =(B12/B13)-1 -> 0.0073099415 | D12: =LN(B12/B13) -> 0.0072833534 | F12: Prom Anual | G12: =G11*252 -> -0.1591975 | H12: =H11*252 -> -0.25586015
A13: 11.04.2025 | B13: 6.84 | C13: =(B13/B14)-1 -> 0.017857143 | D13: =LN(B13/B14) -> 0.017699577 | F13: Desv. | G13: =STDEVA(C2:C1259) -> 0.027896638 | H13: =STDEVA(D2:D1259) -> 0.027605639
A14: 10.04.2025 | B14: 6.72 | C14: =(B14/B15)-1 -> -0.041369472 | D14: =LN(B14/B15) -> -0.042249547 | F14: Desv. Anual | G14: =G13*SQRT(252) -> 0.4428454 | H14: =H13*(252)^(1/2) -> 0.43822593
A15: 09.04.2025 | B15: 7.01 | C15: =(B15/B16)-1 -> 0.050974513 | D15: =LN(B15/B16) -> 0.049717841 | F15: Varianza | G15: =VARA(C2:C1259) -> 0.00077822241 | H15: =VARA(D2:D1259) -> 0.00076207128
A16: 08.04.2025 | B16: 6.67 | C16: =(B16/B17)-1 -> 0.0075528701 | D16: =LN(B16/B17) -> 0.00752449 | F16: Volatilidad | G16: =SQRT(G15) -> 0.027896638 | H16: =SQRT(H15) -> 0.027605639
A17: 07.04.2025 | B17: 6.62 | C17: =(B17/B18)-1 -> -0.029325513 | D17: =LN(B17/B18) -> -0.029764102
A18: 04.04.2025 | B18: 6.82 | C18: =(B18/B19)-1 -> -0.022922636 | D18: =LN(B18/B19) -> -0.023189445
A19: 03.04.2025 | B19: 6.98 | C19: =(B19/B20)-1 -> -0.037241379 | D19: =LN(B19/B20) -> -0.037952552
A20: 02.04.2025 | B20: 7.25 | C20: =(B20/B21)-1 -> 0.011157601 | D20: =LN(B20/B21) -> 0.011095814
A21: 01.04.2025 | B21: 7.17 | C21: =(B21/B22)-1 -> 0.012711864 | D21: =LN(B21/B22) -> 0.012631747
A22: 31.03.2025 | B22: 7.08 | C22: =(B22/B23)-1 -> 0.0056818182 | D22: =LN(B22/B23) -> 0.0056657375
A23: 28.03.2025 | B23: 7.04 | C23: =(B23/B24)-1 -> -0.024930748 | D23: =LN(B23/B24) -> -0.025246783
A24: 27.03.2025 | B24: 7.22 | C24: =(B24/B25)-1 -> 0.015471167 | D24: =LN(B24/B25) -> 0.015352709
A25: 26.03.2025 | B25: 7.11 | C25: =(B25/B26)-1 -> -0.022008253 | D25: =LN(B25/B26) -> -0.022254048
A26: 25.03.2025 | B26: 7.27 | C26: =(B26/B27)-1 -> 0.037089872 | D26: =LN(B26/B27) -> 0.03641859
A27: 24.03.2025 | B27: 7.01 | C27: =(B27/B28)-1 -> 0.027859238 | D27: =LN(B27/B28) -> 0.027478229
A28: 21.03.2025 | B28: 6.82 | C28: =(B28/B29)-1 -> -0.011594203 | D28: =LN(B28/B29) -> -0.01166194
... A1260: 30.04.2020 | B1260: 25.61 | C1260: =(B1260/B1261)-1 -> #DIV/0! | D1260: =LN(B1260/B1261) -> #DIV/0!

Sheet WALMEX
A1: Fecha | B1: Precio | C1: Rend. (Día) | D1: Rend. (Ln) | F1: Precio.Act | G1: =B2 -> 62.15
A2: 30.04.2025 | B2: 62.15 | C2: =(B2/B3)-1 -> 0.040689886 | D2: =LN(B2/B3) -> 0.039883845 | F2: Min | G2: =MIN(B2:B1260) -> 50.32
A3: 29.04.2025 | B3: 59.72 | C3: =(B3/B4)-1 -> -0.04064257 | D3: =LN(B3/B4) -> -0.041491563 | F3: Max | G3: =MAX(B2:B1260) -> 81.92
A4: 28.04.2025 | B4: 62.25 | C4: =(B4/B5)-1 -> 0.018654885 | D4: =LN(B4/B5) -> 0.018483016 | F4: Prom | G4: =AVERAGE(B2:B1260) -> 65.486827
A5: 25.04.2025 | B5: 61.11 | C5: =(B5/B6)-1 -> -0.022865366 | D5: =LN(B5/B6) -> -0.023130833 | F5: Desv. | G5: =STDEVA(B2:B1260) -> 7.1124496
A6: 24.04.2025 | B6: 62.54 | C6: =(B6/B7)-1 -> 0.005789643 | D6: =LN(B6/B7) -> 0.0057729474
A7: 23.04.2025 | B7: 62.18 | C7: =(B7/B8)-1 -> -0.020941584 | D7: =LN(B7/B8) -> -0.021163969
A8: 22.04.2025 | B8: 63.51 | C8: =(B8/B9)-1 -> 0.044744201 | D8: =LN(B8/B9) -> 0.043772072 | F8: RENDIMIENTO | G8: Diario | H8: Ln
A9: 21.04.2025 | B9: 60.79 | C9: =(B9/B10)-1 -> 0.032438859 | D9: =LN(B9/B10) -> 0.031923827 | F9: Min | G9: =MIN(C2:C1259) -> -0.066507095 | H9: =MIN(D2:D1259) -> -0.068821917
A10: 16.04.2025 | B10: 58.88 | C10: =(B10/B11)-1 -> 0.031354002 | D10: =LN(B10/B11) -> 0.030872504 | F10: Max | G10: =MAX(C2:C1259) -> 0.07530648 | H10: =MAX(D2:D1259) -> 0.072605718
A11: 15.04.2025 | B11: 57.09 | C11: =(B11/B12)-1 -> 0.0086572438 | D11: =LN(B11/B12) -> 0.0086199848 | F11: Prom (Rendimiento Esperado) | G11: =AVERAGE(C2:C1259) -> 0.00019221533 | H11: =AVERAGE(D2:D1259) -> 5.5345932e-05
A12: 14.04.2025 | B12: 56.6 | C12: =(B12/B13)-1 -> 0.01688825 | D12: =LN(B12/B13) -> 0.016747229 | F12: Prom Anual | G12: =G11*252 -> 0.048438263 | H12: =H11*252 -> 0.013947175
A13: 11.04.2025 | B13: 55.66 | C13: =(B13/B14)-1 -> -0.0090795798 | D13: =LN(B13/B14) -> -0.0091210504 | F13: Desv. | G13: =STDEVA(C2:C1259) -> 0.016564773 | H13: =STDEVA(D2:D1259) -> 0.016545955
A14: 10.04.2025 | B14: 56.17 | C14: =(B14/B15)-1 -> -0.030381495 | D14: =LN(B14/B15) -> -0.030852579 | F14: Desv. Anual | G14: =G13*SQRT(252) -> 0.26295762 | H14: =H13*SQRT(252) -> 0.26265889
A15: 09.04.2025 | B15: 57.93 | C15: =(B15/B16)-1 -> 0.028404048 | D15: =LN(B15/B16) -> 0.028008132 | F15: Varianza | G15: =VARA(C2:C1259) -> 0.00027439171 | H15: =VARA(D2:D1259) -> 0.00027376862
A16: 08.04.2025 | B16: 56.33 | C16: =(B16/B17)-1 -> -0.010886743 | D16: =LN(B16/B17) -> -0.010946437 | F16: Volatilidad | G16: =SQRT(G15) -> 0.016564773 | H16: =SQRT(H15) -> 0.016545955
A17: 07.04.2025 | B17: 56.95 | C17: =(B17/B18)-1 -> 0.0026408451 | D17: =LN(B17/B18) -> 0.0026373642
A18: 04.04.2025 | B18: 56.8 | C18: =(B18/B19)-1 -> -0.043448973 | D18: =LN(B18/B19) -> -0.044421144
A19: 03.04.2025 | B19: 59.38 | C19: =(B19/B20)-1 -> 0.02573847 | D19: =LN(B19/B20) -> 0.025412811
A20: 02.04.2025 | B20: 57.89 | C20: =(B20/B21)-1 -> 0.011709193 | D20: =LN(B20/B21) -> 0.01164117
A21: 01.04.2025 | B21: 57.22 | C21: =(B21/B22)-1 -> 0.015259049 | D21: =LN(B21/B22) -> 0.015143801
A22: 31.03.2025 | B22: 56.36 | C22: =(B22/B23)-1 -> -0.016061453 | D22: =LN(B22/B23) -> -0.016191836
A23: 28.03.2025 | B23: 57.28 | C23: =(B23/B24)-1 -> -0.019010104 | D23: =LN(B23/B24) -> -0.01919312
A24: 27.03.2025 | B24: 58.39 | C24: =(B24/B25)-1 -> 0.035283688 | D24: =LN(B24/B25) -> 0.034675484
A25: 26.03.2025 | B25: 56.4 | C25: =(B25/B26)-1 -> 0.0015982952 | D25: =LN(B25/B26) -> 0.0015970192
A26: 25.03.2025 | B26: 56.31 | C26: =(B26/B27)-1 -> 0.0032068413 | D26: =LN(B26/B27) -> 0.0032017103
A27: 24.03.2025 | B27: 56.13 | C27: =(B27/B28)-1 -> -0.00071212391 | D27: =LN(B27/B28) -> -0.00071237759
A28: 21.03.2025 | B28: 56.17 | C28: =(B28/B29)-1 -> 0.025374224 | D28: =LN(B28/B29) -> 0.025057643
... A1260: 30.04.2020 | B1260: 57.97 | C1260: =(B1260/B1261)-1 -> #DIV/0! | D1260: =LN(B1260/B1261) -> #DIV/0!

Sheet KIMBERA
A1: Fecha | B1: Precio | C1: Rend. (Día) | D1: Rend. (Ln) | F1: Precio.Act | G1: =B2 -> 34.57
A2: 30.04.2025 | B2: 34.57 | C2: =(B2/B3)-1 -> 0.023386619 | D2: =LN(B2/B3) -> 0.023117343 | F2: Min | G2: =MIN(B2:B1260) -> 25.61
A3: 29.04.2025 | B3: 33.78 | C3: =(B3/B4)-1 -> -0.034305317 | D3: =LN(B3/B4) -> -0.034907558 | F3: Max | G3: =MAX(B2:B1260) -> 40.79
A4: 28.04.2025 | B4: 34.98 | C4: =(B4/B5)-1 -> 0.028521023 | D4: =LN(B4/B5) -> 0.028121871 | F4: Prom | G4: =AVERAGE(B2:B1260) -> 33.564575
A5: 25.04.2025 | B5: 34.01 | C5: =(B5/B6)-1 -> 0.023780855 | D5: =LN(B5/B6) -> 0.023502495 | F5: Desv. | G5: =STDEVA(B2:B1260) -> 3.5297658
A6: 24.04.2025 | B6: 33.22 | C6: =(B6/B7)-1 -> 0.0097264438 | D6: =LN(B6/B7) -> 0.0096794464
A7: 23.04.2025 | B7: 32.9 | C7: =(B7/B8)-1 -> 0.0067319461 | D7: =LN(B7/B8) -> 0.0067093878
A8: 22.04.2025 | B8: 32.68 | C8: =(B8/B9)-1 -> -0.0075918615 | D8: =LN(B8/B9) -> -0.0076208264 | F8: RENDIMIENTO | G8: Diario | H8: Ln
A9: 21.04.2025 | B9: 32.93 | C9: =(B9/B10)-1 -> 0.0061106019 | D9: =LN(B9/B10) -> 0.0060920079 | F9: Min | G9: =MIN(C2:C1260) -> #DIV/0! | H9: =MIN(D2:D1246) -> -0.058199538
A10: 16.04.2025 | B10: 32.73 | C10: =(B10/B11)-1 -> -0.0012206286 | D10: =LN(B10/B11) -> -0.0012213742 | F10: Max | G10: =MAX(C2:C1246) -> 0.065381708 | H10: =MAX(D2:D1246) -> 0.063333146
A11: 15.04.2025 | B11: 32.77 | C11: =(B11/B12)-1 -> 0.012982998 | D11: =LN(B11/B12) -> 0.012899442 | F11: Prom (Rendimiento Esperado) | G11: =AVERAGE(C2:C1246) -> 0.00013599974 | H11: =AVERAGE(D2:D1246) -> -2.323103e-07
A12: 14.04.2025 | B12: 32.35 | C12: =(B12/B13)-1 -> 0.018576826 | D12: =LN(B12/B13) -> 0.018406385 | F12: Prom Anual | G12: =G11*252 -> 0.034271933 | H12: =H11*252 -> -5.8542195e-05
A13: 11.04.2025 | B13: 31.76 | C13: =(B13/B14)-1 -> -0.0105919 | D13: =LN(B13/B14) -> -0.010648394 | F13: Desv. | G13: =STDEVA(C2:C1246) -> 0.016530534 | H13: =STDEVA(D2:D1246) -> 0.016505596
A14: 10.04.2025 | B14: 32.1 | C14: =(B14/B15)-1 -> -0.03371463 | D14: =LN(B14/B15) -> -0.034296074 | F14: Desv. Anual | G14: =G13*SQRT(252) -> 0.26241409 | H14: =H13*SQRT(252) -> 0.26201822
A15: 09.04.2025 | B15: 33.22 | C15: =(B15/B16)-1 -> 0.054268486 | D15: =LN(B15/B16) -> 0.052847148 | F15: Varianza | G15: =VARA(C2:C1246) -> 0.00027325855 | H15: =VARA(D2:D1246) -> 0.00027243471
A16: 08.04.2025 | B16: 31.51 | C16: =(B16/B17)-1 -> -0.023551286 | D16: =LN(B16/B17) -> -0.02383305 | F16: Volatilidad | G16: =SQRT(G15) -> 0.016530534 | H16: =SQRT(H15) -> 0.016505596
A17: 07.04.2025 | B17: 32.27 | C17: =(B17/B18)-1 -> -0.029473684 | D17: =LN(B17/B18) -> -0.029916761
A18: 04.04.2025 | B18: 33.25 | C18: =(B18/B19)-1 -> 0.0054429997 | D18: =LN(B18/B19) -> 0.0054282401
A19: 03.04.2025 | B19: 33.07 | C19: =(B19/B20)-1 -> 0.018478596 | D19: =LN(B19/B20) -> 0.018309941
A20: 02.04.2025 | B20: 32.47 | C20: =(B20/B21)-1 -> -0.020808203 | D20: =LN(B20/B21) -> -0.021027744
A21: 01.04.2025 | B21: 33.16 | C21: =(B21/B22)-1 -> -0.011624441 | D21: =LN(B21/B22) -> -0.011692533
A22: 31.03.2025 | B22: 33.55 | C22: =(B22/B23)-1 -> -0.00089338892 | D22: =LN(B22/B23) -> -0.00089378823
A23: 28.03.2025 | B23: 33.58 | C23: =(B23/B24)-1 -> 0.010532651 | D23: =LN(B23/B24) -> 0.010477569
A24: 27.03.2025 | B24: 33.23 | C24: =(B24/B25)-1 -> 0.0045344619 | D24: =LN(B24/B25) -> 0.0045242122
A25: 26.03.2025 | B25: 33.08 | C25: =(B25/B26)-1 -> 0.0088441598 | D25: =LN(B25/B26) -> 0.0088052793
A26: 25.03.2025 | B26: 32.79 | C26: =(B26/B27)-1 -> 0.0055197792 | D26: =LN(B26/B27) -> 0.0055046011
A27: 24.03.2025 | B27: 32.61 | C27: =(B27/B28)-1 -> 0.0036934441 | D27: =LN(B27/B28) -> 0.0036866401
A28: 21.03.2025 | B28: 32.49 | C28: =(B28/B29)-1 -> -0.0049004594 | D28: =LN(B28/B29) -> -0.004912506
... A1260: 30.04.2020 | B1260: 34.04 | C1260: =(B1260/B1261)-1 -> #DIV/0! | D1260: =LN(B1260/B1261) -> #DIV/0!

Sheet Inversa
B2: Matriz de varianzas y covarianzas (MVC) muestrales | K2: MVC Extendida | V2: Portafolio min varianza
C4: GFNORTEO | D4: KOFUBL | E4: TLEVISACPO | F4: WALMEX | G4: KIMBERA | I4: Rendimiento E | L4: GFNORTEO | M4: KOFUBL | N4: TLEVISACPO | O4: WALMEX | P4: KIMBERA | S4: B | V4: w_GFNORTEO | W4: {=MMULT(MINVERSE(L5:Q10),S5:S10)} -> 0.079043523 | X4: =SUM(W4:W8) -> 1
B5: GFNORTEO | C5: =+_xlfn.VAR.S(GFNORTEO!C2:C1259) -> 0.00048130731 | D5: =+C6 -> 6.210373e-05 | E5: =+C7 -> 0.00015183542 | F5: =+C8 -> 9.9748217e-05 | G5: =+C9 -> 7.8803206e-05 | I5: =+AVERAGE(GFNORTEO!C2:C1259) -> 0.00098655288 | K5: GFNORTEO | L5: =C5 -> 0.00048130731 | M5: =D5 -> 6.210373e-05 | N5: =E5 -> 0.00015183542 | O5: =F5 -> 9.9748217e-05 | P5: =G5 -> 7.8803206e-05 | Q5: 1 | S5: 0 | V5: w_KOFUBL | W5: 0.37308022
B6: KOFUBL | C6: =+_xlfn.COVARIANCE.S(GFNORTEO!C2:C1259,KOFUBL!C2:C1259) -> 6.210373e-05 | D6: =+_xlfn.VAR.S(KOFUBL!C2:C1259) -> 0.00021789708 | E6: =+D7 -> 8.4799454e-05 | F6: =+D8 -> 4.0451061e-05 | G6: =+D9 -> 4.8782385e-05 | I6: =+AVERAGE(KOFUBL!C2:C1259) -> 0.00061998579 | K6: KOFUBL | L6: =C6 -> 6.210373e-05 | M6: =D6 -> 0.00021789708 | N6: =E6 -> 8.4799454e-05 | O6: =F6 -> 4.0451061e-05 | P6: =G6 -> 4.8782385e-05 | Q6: 1 | S6: 0 | V6: w_TLEVISACPO | W6: 0.020507432
B7: TLEVISACPO | C7: =+_xlfn.COVARIANCE.S(GFNORTEO!C2:C1259,TLEVISACPO!C2:C1259) -> 0.00015183542 | D7: =+_xlfn.COVARIANCE.S(KOFUBL!C2:C1259,TLEVISACPO!C2:C1259) -> 8.4799454e-05 | E7: =+_xlfn.VAR.S(TLEVISACPO!C2:C1259) -> 0.00077822241 | F7: =+E8 -> 9.7959123e-05 | G7: =+E9 -> 9.8702345e-05 | I7: =+AVERAGE(TLEVISACPO!C2:C1259) -> -0.00063173613 | K7: TLEVISACPO | L7: =C7 -> 0.00015183542 | M7: =D7 -> 8.4799454e-05 | N7: =E7 -> 0.00077822241 | O7: =F7 -> 9.7959123e-05 | P7: =G7 -> 9.8702345e-05 | Q7: 1 | S7: 0 | V7: w_WALMEX | W7: 0.2657884
B8: WALMEX | C8: =+_xlfn.COVARIANCE.S(GFNORTEO!C2:C1259,WALMEX!C2:C1259) -> 9.9748217e-05 | D8: =+_xlfn.COVARIANCE.S(KOFUBL!C2:C1259,WALMEX!C2:C1259) -> 4.0451061e-05 | E8: =+_xlfn.COVARIANCE.S(TLEVISACPO!C2:C1259,WALMEX!C2:C1259) -> 9.7959123e-05 | F8: =+_xlfn.VAR.S(WALMEX!C2:C1259) -> 0.00027439171 | G8: =+F9 -> 5.1754577e-05 | I8: =+AVERAGE(WALMEX!C2:C1259) -> 0.00019221533 | K8: WALMEX | L8: =C8 -> 9.9748217e-05 | M8: =D8 -> 4.0451061e-05 | N8: =E8 -> 9.7959123e-05 | O8: =F8 -> 0.00027439171 | P8: =G8 -> 5.1754577e-05 | Q8: 1 | S8: 0 | V8: w_KIMBERA | W8: 0.26158042
B9: KIMBERA | C9: =+_xlfn.COVARIANCE.S(GFNORTEO!C2:C1259,KIMBERA!C2:C1259) -> 7.8803206e-05 | D9: =+_xlfn.COVARIANCE.S(KOFUBL!C2:C1259,KIMBERA!C2:C1259) -> 4.8782385e-05 | E9: =+_xlfn.COVARIANCE.S(TLEVISACPO!C2:C1259,KIMBERA!C2:C1259) -> 9.8702345e-05 | F9: =+_xlfn.COVARIANCE.S(WALMEX!C2:C1259,KIMBERA!C2:C1259) -> 5.1754577e-05 | G9: =+_xlfn.VAR.S(KIMBERA!C2:C1259) -> 0.00027236146 | I9: =+AVERAGE(KIMBERA!C2:C1259) -> 0.00014808837 | K9: KIMBERA | L9: =C9 -> 7.8803206e-05 | M9: =D9 -> 4.8782385e-05 | N9: =E9 -> 9.8702345e-05 | O9: =F9 -> 5.1754577e-05 | P9: =G9 -> 0.00027236146 | Q9: 1 | S9: 0 | W9: -0.00011145295
L10: 1 | M10: 1 | N10: 1 | O10: 1 | P10: 1 | Q10: 0 | S10: 1
B11: Coef correlacion
V12: Rendimiento | W12: {=MMULT(TRANSPOSE(W4:W8),I5:I9)} -> 0.00038615539
C13: GFNORTEO | D13: KOFUBL | E13: TLEVISACPO | F13: WALMEX | G13: KIMBERA | V13: Varianza | W13: {=MMULT(MMULT(TRANSPOSE(W4:W8),C5:G9),W4:W8)} -> 0.00011145295
B14: GFNORTEO | C14: =+CORREL(GFNORTEO!C2:C1259,GFNORTEO!C2:C1259) -> 1 | D14: =+C15 -> 0.19177004 | E14: =+C16 -> 0.24809042 | F14: =+C17 -> 0.27447856 | G14: =+C18 -> 0.21765058 | V14: Volatilidad | W14: =SQRT(W13) -> 0.010557128
B15: KOFUBL | C15: =+CORREL(GFNORTEO!C2:C1259,KOFUBL!C2:C1259) -> 0.19177004 | D15: =+CORREL(KOFUBL!C2:C1259,KOFUBL!C2:C1259) -> 1 | E15: =+D16 -> 0.20592804 | F15: =+D17 -> 0.16543169 | G15: =+D18 -> 0.2002463 | K15: MVC Inversa aumentada
B16: TLEVISACPO | C16: =+CORREL(GFNORTEO!C2:C1259,TLEVISACPO!C2:C1259) -> 0.24809042 | D16: =+CORREL(KOFUBL!C2:C1259,TLEVISACPO!C2:C1259) -> 0.20592804 | E16: =+CORREL(TLEVISACPO!C2:C1256,TLEVISACPO!C2:C1256) -> 1 | F16: =+E17 -> 0.21198617 | G16: =+E18 -> 0.21438914 | W16: Activo libre de riesgo
B17: WALMEX | C17: =+CORREL(GFNORTEO!C2:C1259,WALMEX!C2:C1259) -> 0.27447856 | D17: =+CORREL(KOFUBL!C2:C1259,WALMEX!C2:C1259) -> 0.16543169 | E17: =+CORREL(TLEVISACPO!C2:C1259,WALMEX!C2:C1259) -> 0.21198617 | F17: =+CORREL(WALMEX!C2:C1256,WALMEX!C2:C1256) -> 1 | G17: =+F18 -> 0.18931736 | L17: GFNORTEO | M17: KOFUBL | N17: TLEVISACPO | O17: WALMEX | P17: KIMBERA | U17: W | W17: Cete a 28 dias
B18: KIMBERA | C18: =+CORREL(GFNORTEO!C2:C1259,KIMBERA!C2:C1259) -> 0.21765058 | D18: =+CORREL(KOFUBL!C2:C1259,KIMBERA!C2:C1259) -> 0.2002463 | E18: =+CORREL(TLEVISACPO!C2:C1259,KIMBERA!C2:C1259) -> 0.21438914 | F18: =+CORREL(WALMEX!C2:C1259,KIMBERA!C2:C1259) -> 0.18931736 | G18: =+CORREL(KIMBERA!C2:C1256,KIMBERA!C2:C1256) -> 1 | K18: GFNORTEO | L18: {=MINVERSE(L5:Q10)} -> 2362.3876 | M18: -627.37169 | N18: -314.78717 | O18: -830.81386 | P18: -589.4149 | Q18: 0.079043523 | U18: {=MMULT(L18:Q23,S5:S10)} -> 0.079043523 | W18: Rendimiento anual | X18: 0.0902
K19: KOFUBL | L19: -627.37169 | M19: 3784.6813 | N19: -423.92384 | O19: -1260.3601 | P19: -1473.0257 | Q19: 0.37308022 | U19: 0.37308022 | W19: Rendimiento diario | X19: =X18/360 -> 0.00025055556 | Y19: =X19 -> 0.00025055556
B20: MVC INVERSA | K20: TLEVISACPO | L20: -314.78717 | M20: -423.92384 | N20: 1457.0072 | O20: -348.15324 | P20: -370.14299 | Q20: 0.020507432 | U20: 0.020507432 | W20: Volatilidad | X20: 0
K21: WALMEX | L21: -830.81386 | M21: -1260.3601 | N21: -348.15324 | O21: 3485.1561 | P21: -1045.8288 | Q21: 0.2657884 | U21: 0.2657884
C22: GFNORTEO | D22: KOFUBL | E22: TLEVISACPO | F22: WALMEX | G22: KIMBERA | K22: KIMBERA | L22: -589.4149 | M22: -1473.0257 | N22: -370.14299 | O22: -1045.8288 | P22: 3478.4124 | Q22: 0.26158042 | U22: 0.26158042
B23: GFNORTEO | C23: {=MINVERSE(C5:G9)} -> 2418.4461 | D23: -362.77954 | E23: -300.2431 | F23: -642.31412 | G23: -403.89951 | L23: 0.079043523 | M23: 0.37308022 | N23: 0.020507432 | O23: 0.2657884 | P23: 0.26158042 | Q23: -0.00011145295 | U23: -0.00011145295
B24: KOFUBL | C24: -362.77954 | D24: 5033.5389 | E24: -355.27678 | F24: -370.65376 | G24: -597.40523 | Y24: Portafolio optimo
B25: TLEVISACPO | C25: -300.2431 | D25: -355.27678 | E25: 1460.7806 | F25: -299.24796 | G25: -322.01198
B26: WALMEX | C26: -642.31412 | D26: -370.65376 | E26: -299.24796 | F26: 4118.9973 | G26: -422.02263 | U26: E-rf | W26: Z | Y26: w_AMZN | Z26: =W27/SUM($W$27:$W$31) -> 1.6353926
B27: KIMBERA | C27: -403.89951 | D27: -597.40523 | E27: -322.01198 | F27: -422.02263 | G27: 4092.3425 | U27: =I5-$X$19 -> 0.00073599733 | W27: {=MMULT(MINVERSE(C5:G9),U27:U31)} -> 1.9897093 | Y27: w_BA | Z27: =W28/SUM($W$27:$W$31) -> 1.6346722
U28: =I6-$X$19 -> 0.00036943024 | W28: 1.9888329 | Y28: w_SPOT | Z28: =W29/SUM($W$27:$W$31) -> -1.3073618
B29: MVC Aumentada X2 | K29: MVC Aumentada X2 Inversa | U29: =I7-$X$19 -> -0.00088229168 | W29: -1.5906088 | Y29: w_MAT | Z29: =W30/SUM($W$27:$W$31) -> -0.44606544 | AA29: =SUM(Z26:Z30) -> 1
U30: =I8-$X$19 -> -5.8340224e-05 | W30: -0.54270795 | Y30: w_HLT | Z30: =W31/SUM($W$27:$W$31) -> -0.51663759
C31: GFNORTEO | D31: KOFUBL | E31: TLEVISACPO | F31: WALMEX | G31: KIMBERA | L31: GFNORTEO | M31: KOFUBL | N31: TLEVISACPO | O31: WALMEX | P31: KIMBERA | U31: =I9-$X$19 -> -0.00010246719 | W31: -0.62856994 | Y31: Rendimiento esperado | AA31: =AC31 -> 0.0032905338 | AC31: {=MMULT(TRANSPOSE(Z26:Z30),I5:I9)} -> 0.0032905338
B32: GFNORTEO | C32: =C5 -> 0.00048130731 | D32: =D5 -> 6.210373e-05 | E32: =E5 -> 0.00015183542 | F32: =F5 -> 9.9748217e-05 | G32: =G5 -> 7.8803206e-05 | H32: 1 | I32: =I5 -> 0.00098655288 | K32: GFNORTEO | L32: {=MINVERSE(C32:I38)} -> 1347.7092 | M32: -1449.8801 | N32: 550.93134 | O32: -366.71314 | P32: -82.047363 | Q32: -0.12788288 | R32: 535.86303 | Y32: Varianza | Z32: {=MMULT(MMULT(TRANSPOSE(Z26:Z30),C5:G9),Z26:Z30)} -> 0.0024986353
B33: KOFUBL | C33: =C6 -> 6.210373e-05 | D33: =D6 -> 0.00021789708 | E33: =E6 -> 8.4799454e-05 | F33: =F6 -> 4.0451061e-05 | G33: =G6 -> 4.8782385e-05 | H33: 1 | I33: =I6 -> 0.00061998579 | K33: KOFUBL | L33: -1449.8801 | M33: 3117.9479 | N33: 277.8362 | O33: -884.15547 | P33: -1061.7485 | Q33: 0.20534363 | R33: 434.37591 | U33: B | X33: W Ef | Y33: Volatilidad | Z33: =SQRT(Z32) -> 0.049986351
B34: TLEVISACPO | C34: =C7 -> 0.00015183542 | D34: =D7 -> 8.4799454e-05 | E34: =E7 -> 0.00077822241 | F34: =F7 -> 9.7959123e-05 | G34: =G7 -> 9.8702345e-05 | H34: 1 | I34: =I7 -> -0.00063173613 | K34: TLEVISACPO | L34: 550.93134 | M34: 277.8362 | N34: 718.38054 | O34: -744.12165 | P34: -803.02644 | Q34: 0.197056 | R34: -457.19566 | U34: 0 | W34: {=MMULT(L32:R38,U34:U40)} -> 1.4797062 | X34: {=MMULT(L32:R38,U34:U40)} -> 1.4797062
B35: WALMEX | C35: =C8 -> 9.9748217e-05 | D35: =D8 -> 4.0451061e-05 | E35: =E8 -> 9.7959123e-05 | F35: =F8 -> 0.00027439171 | G35: =G8 -> 5.1754577e-05 | H35: 1 | I35: =I8 -> 0.00019221533 | K35: WALMEX | L35: -366.71314 | M35: -884.15547 | N35: -744.12165 | O35: 3272.8824 | P35: -1277.8922 | Q35: 0.36043385 | R35: -245.09679 | U35: 0 | W35: 1.5084713 | X35: 1.5084713 | Y35: =SUM(X34:X38) -> 1
B36: KIMBERA | C36: =C9 -> 7.8803206e-05 | D36: =D9 -> 4.8782385e-05 | E36: =E9 -> 9.8702345e-05 | F36: =F9 -> 5.1754577e-05 | G36: =G9 -> 0.00027236146 | H36: 1 | I36: =I9 -> 0.00014808837 | K36: KIMBERA | L36: -82.047363 | M36: -1061.7485 | N36: -803.02644 | O36: -1277.8922 | P36: 3224.7145 | Q36: 0.3650494 | R36: -267.94649 | U36: 0 | W36: -1.174531 | X36: -1.174531
C37: 1 | D37: 1 | E37: 1 | F37: 1 | G37: 1 | H37: 0 | I37: 0 | L37: -0.12788288 | M37: 0.20534363 | N37: 0.197056 | O37: 0.36043385 | P37: 0.3650494 | Q37: -0.00015365207 | R37: 0.10928015 | U37: 0 | W37: -0.37485653 | X37: -0.37485653
C38: =I32 -> 0.00098655288 | D38: =I33 -> 0.00061998579 | E38: =I34 -> -0.00063173613 | F38: =I35 -> 0.00019221533 | G38: =I36 -> 0.00014808837 | H38: 0 | I38: 0 | L38: 535.86303 | M38: 434.37591 | N38: -457.19566 | O38: -245.09679 | P38: -267.94649 | Q38: 0.10928015 | R38: -282.99528 | U38: 0 | W38: -0.43879007 | X38: -0.43879007
U39: 1 | W39: 0.00017418839 | X39: 0.00017418839
B40: Frontera ef | T40: rend ef | U40: 0.003 | W40: -0.73970568 | X40: -0.73970568
B42: w_GFNORTEO | C42: w_KOFUBL | D42: w_TLEVISACPO | E42: w_WALMEX | F42: w_KIMBERA | G42: Var | H42: Volatillidad | I42: Rendimiento esperado | L42: Tasa prestamo
A43: 1 | B43: 0.079043523 | C43: 0.37308022 | D43: 0.020507432 | E43: 0.2657884 | F43: 0.26158042 | G43: {=MMULT(MMULT(B43:F43,$C$5:$G$9),TRANSPOSE(B43:F43))} -> 0.00011145295 | H43: =SQRT(G43) -> 0.010557128 | I43: {=MMULT(B43:F43,$I$5:$I$9)} -> 0.00038615539 | J43: Min var | P43: tasa de prestamo
...

Sheet Portafolio
D2: PORTAFOLIO MINIMA VARIANZA
C3: CAPITAL | D3: y | E3: rf | F3: PR | G3: INV_GFNORTEO | H3: INV_KOFUBL | I3: INV_TLEVISACPO | J3: INV_WALMEX | K3: INV_KIMBERA | L3: Rendimiento | M3: premio al riesgo
B4: INV 1 | C4: 100000000 | D4: 0.25 | E4: =(1-D4)*C4 -> 75000000 | F4: =D4*C4 -> 25000000 | G4: =F4*Inversa!$B$43 -> 1976088.1 | H4: =F4*Inversa!$C$43 -> 9327005.6 | I4: =F4*Inversa!$D$43 -> 512685.8 | J4: =F4*Inversa!$E$43 -> 6644710.1 | K4: =F4*Inversa!$F$43 -> 6539510.4 | L4: =(D4*Inversa!$I$43)+(1-D4)*Inversa!$X$19 -> 0.00028445551 | M4: =L4-Inversa!$X$19 -> 3.3899959e-05
B5: INV 2 | C5: 500000 | D5: 0.85 | E5: =(1-D5)*C5 -> 75000 | F5: =D5*C5 -> 425000 | G5: =F5*Inversa!$B$43 -> 33593.497 | H5: =F5*Inversa!$C$43 -> 158559.1 | I5: =F5*Inversa!$D$43 -> 8715.6585 | J5: =F5*Inversa!$E$43 -> 112960.07 | K5: =F5*Inversa!$F$43 -> 111171.68 | L5: =(D5*Inversa!$I$43)+(1-D5)*Inversa!$X$19 -> 0.00036581542 | M5: =L5-Inversa!$X$19 -> 0.00011525986
B6: INV 3 | C6: 1500000 | D6: 1.3 | E6: =(1-D6)*C6 -> -450000 | F6: =D6*C6 -> 1950000 | G6: =F6*Inversa!$B$43 -> 154134.87 | H6: =F6*Inversa!$C$43 -> 727506.44 | I6: =F6*Inversa!$D$43 -> 39989.492 | J6: =F6*Inversa!$E$43 -> 518287.39 | K6: =F6*Inversa!$F$43 -> 510081.81 | L6: =(D6*Inversa!$I$43)+(1-D6)*Inversa!$X$19 -> 0.00042683534 | M6: =L6-Inversa!$X$19 -> 0.00017627979
D8: PORTAFOLIO OPTIMO
C9: CAPITAL | D9: y | E9: rf | F9: PR | G9: INV_GFNORTEO | H9: INV_KOFUBL | I9: INV_TLEVISACPO | J9: INV_WALMEX | K9: INV_KIMBERA | L9: Rendimiento | M9: premio al riesgo
B10: INV 1 | C10: =C4 -> 100000000 | D10: 0.25 | E10: =(1-D10)*C10 -> 75000000 | F10: =D10*C10 -> 25000000 | G10: =F10*Inversa!$B$67 -> 40884814 | H10: =F10*Inversa!$C$67 -> 40866806 | I10: =F10*Inversa!$D$67 -> -32684044 | J10: =F10*Inversa!$E$67 -> -11151636 | K10: =F10*Inversa!$F$67 -> -12915940 | L10: =(D10*Inversa!$I$67)+(1-D10)*Inversa!$X$19 -> 0.0010105501 | M10: =L10-Inversa!$X$19 -> 0.00075999457
B11: INV 2 | C11: =C5 -> 500000 | D11: 0.85 | E11: =(1-D11)*C11 -> 75000 | F11: =D11*C11 -> 425000 | G11: =F11*Inversa!$B$67 -> 695041.84 | H11: =F11*Inversa!$C$67 -> 694735.7 | I11: =F11*Inversa!$D$67 -> -555628.76 | J11: =F11*Inversa!$E$67 -> -189577.81 | K11: =F11*Inversa!$F$67 -> -219570.98 | L11: =(D11*Inversa!$I$67)+(1-D11)*Inversa!$X$19 -> 0.0028345371 | M11: =L11-Inversa!$X$19 -> 0.0025839815
B12: INV 3 | C12: =C6 -> 1500000 | D12: 1.3 | E12: =(1-D12)*C12 -> -450000 | F12: =D12*C12 -> 1950000 | G12: =F12*Inversa!$B$67 -> 3189015.5 | H12: =F12*Inversa!$C$67 -> 3187610.9 | I12: =F12*Inversa!$D$67 -> -2549355.5 | J12: =F12*Inversa!$E$67 -> -869827.61 | K12: =F12*Inversa!$F$67 -> -1007443.3 | L12: =(D12*Inversa!$I$67)+(1-D12)*Inversa!$X$19 -> 0.0042025273 | M12: =L12-Inversa!$X$19 -> 0.0039519718
