Workbook

Sheet Prima Tarifa
F2: Seguro de Rentas Vitalicias | J2: Calculo de Prima Tarifa
B4: Moneda | C4: Pesos | H4: Caso 1 | K4: Caso 2
B6: Edad Contratación | C6: 65 | D6: =IF(C6>100,"FUERA DE RANGO","") | E6: Valor Anualidad | F6: =Anual!K4+Mensual!M6 -> 20.370346 | H6: ¿Cuánto pagará de prima única? | I6: 1000000 | K6: ¿Cuánto desea recibir de Renta Mensual? | L6: 15000
B8: Plazo del Seguro (w-x) | C8: =Anual!H6 -> 35 | E8: Tasa interes técnico | F8: 0.0947 | H8: Recibirás una Renta Mensual de: | I8: =(I6-(C12+C13+C14)*I6)/(Mensual!M6+0.5*Anual!K4) -> 43287.631 | K8: Recibirás de Renta Anual: | L8: =0.5*L6 -> 7500
E10: Tasa mensual | F10: =12*(((1+F8)^(1/12))-1) -> 0.090822324 | H10: Recibirás una Renta Anual de: | I10: =0.5*I8 -> 21643.815 | K10: Debes pagar de Prima Tarifa | L10: ='Prima Riesgo'!L10/(1-(C12+C13+C14)) -> 346519.31
B12: Gastos Administración | C12: 0.1
B13: Gastos Adquisición | C13: 0.12
B14: Margen Utilidades | C14: 0.08

Sheet Prima Riesgo
F2: Seguro de Rentas Vitalicias | J2: Calculo de Prima Única de Riesgo
B4: Moneda | C4: Pesos | H4: Caso 1 | K4: Caso 2
B6: Edad Contratación | C6: ='Prima Tarifa'!C6 -> 65 | E6: Valor Anualidad | F6: =Anual!K4+Mensual!M6 -> 20.370346 | H6: ¿Cuánto pagará de prima única? | I6: ='Prima Tarifa'!I6 -> 1000000 | K6: ¿Cuánto desea recibir de Renta Mensual? | L6: ='Prima Tarifa'!L6 -> 15000
B8: Plazo del Seguro (w-x) | C8: =Anual!H6 -> 35 | E8: Tasa interes técnico | F8: ='Prima Tarifa'!F8 -> 0.0947 | H8: Recibirás una Renta Mensual de: | I8: =I6/(Mensual!M6+0.5*Anual!K4) -> 61839.472 | K8: Recibirás de Renta Anual: | L8: =0.5*L6 -> 7500
E10: Tasa mensual | F10: =12*(((1+F8)^(1/12))-1) -> 0.090822324 | H10: Recibirás una Renta Anual de: | I10: =0.5*I8 -> 30919.736 | K10: Debes pagar como Prima Única: | L10: =Anual!Q6+Mensual!S8 -> 242563.52

Sheet Mensual
B3: Edad | C3: CNSF 2000-I | D3: qx | E3: lx | F3: dx | G3: px | M3: Seguro de Rentas Vitalicias | Q3: Calculo de de Renta Mensual
B4: 12 | C4: 0.396 | D4: =C4/1000 -> 0.000396 | E4: 1000000 | F4: =D4*E4 -> 396 | G4: =1-D4 -> 0.999604 | I4: Moneda | J4: Pesos
B5: =B4+1/12 -> 12.083333 | D5: =F5/E5 -> 3.3001089e-05 | E5: =E4-(1/12)*F4 -> 999967 | F5: =E5-E6 -> 33 | G5: =1-D5 -> 0.999967
B6: =B5+1/12 -> 12.166667 | D6: =(B6-$B$4)*$D$4 -> 6.6e-05 | E6: =E4-(2/12)*F4 -> 999934 | F6: =E6-E7 -> 33 | G6: =1-D6 -> 0.999934 | I6: Edad Contratación | J6: ='Prima Riesgo'!C6 -> 65 | L6: Valor Anualidad | M6: =T14 -> 11.971456 | O6: ¿Cuánto pagarás de prima única? | P6: ='Prima Riesgo'!I6 -> 1000000 | R6: ¿Cuánto quieres recibir de Renta Mensual? | S6: ='Prima Riesgo'!L6 -> 15000
B7: =B6+1/12 -> 12.25 | D7: =(B7-$B$4)*$D$4 -> 9.9e-05 | E7: =E4-(3/12)*F4 -> 999901 | F7: =E7-E8 -> 33 | G7: =1-D7 -> 0.999901
B8: =B7+1/12 -> 12.333333 | D8: =(B8-$B$4)*$D$4 -> 0.000132 | E8: =E4-(4/12)*F4 -> 999868 | F8: =E8-E9 -> 33 | G8: =1-D8 -> 0.999868 | I8: Plazo del Seguro (w-x) | J8: =B1060-J6 -> 35 | L8: Tasa interes técnico | M8: ='Prima Riesgo'!F8 -> 0.0947 | O8: Recibirás de Renta Mensual: | P8: =P6/T14 -> 83532.025 | R8: Debes pagar como Prima Única: | S8: =S6*T14 -> 179571.85
B9: =B8+1/12 -> 12.416667 | D9: =(B9-$B$4)*$D$4 -> 0.000165 | E9: =E4-(5/12)*F4 -> 999835 | F9: =E9-E10 -> 33 | G9: =1-D9 -> 0.999835
B10: =B9+1/12 -> 12.5 | D10: =(B10-$B$4)*$D$4 -> 0.000198 | E10: =E4-(6/12)*F4 -> 999802 | F10: =E10-E11 -> 33 | G10: =1-D10 -> 0.999802 | L10: Tasa mensual | M10: =12*(((1+M8)^(1/12))-1) -> 0.090822324
B11: =B10+1/12 -> 12.583333 | D11: =(B11-$B$4)*$D$4 -> 0.000231 | E11: =E4-(7/12)*F4 -> 999769 | F11: =E11-E12 -> 33 | G11: =1-D11 -> 0.999769
B12: =B11+1/12 -> 12.666667 | D12: =(B12-$B$4)*$D$4 -> 0.000264 | E12: =E4-(8/12)*F4 -> 999736 | F12: =E12-E13 -> 33 | G12: =1-D12 -> 0.999736
B13: =B12+1/12 -> 12.75 | D13: =(B13-$B$4)*$D$4 -> 0.000297 | E13: =E4-(9/12)*F4 -> 999703 | F13: =E13-E14 -> 33 | G13: =1-D13 -> 0.999703
B14: =B13+1/12 -> 12.833333 | D14: =(B14-$B$4)*$D$4 -> 0.00033 | E14: =E4-(10/12)*F4 -> 999670 | F14: =E14-E15 -> 33 | G14: =1-D14 -> 0.99967 | R14: suma de flujos mensuales | T14: =SUM(T16:T1074) -> 11.971456
B15: =B14+1/12 -> 12.916667 | D15: =(B15-$B$4)*$D$4 -> 0.000363 | E15: =E4-(11/12)*F4 -> 999637 | F15: =E15-E16 -> 33 | G15: =1-D15 -> 0.999637 | I15: t | J15: (x) | K15: qx+t | L15: px | M15: tpx | N15: V^t | Q15: s | R15: spx | S15: V^s | T15: Flujo Anualidad
B16: 13 | C16: 0.427 | D16: =C16/1000 -> 0.000427 | E16: =E4-F4 -> 999604 | F16: =D16*E16 -> 426.83091 | G16: =1-D16 -> 0.999573 | I16: 0 | J16: =J6 -> 65 | K16: =IFERROR(VLOOKUP(J16,$B$3:$F$1060,3,FALSE),"") -> 0.01998 | L16: =IF(I16<>"",1-K16,"") -> 0.98002 | M16: =IF(I16<>"",1,"") -> 1 | N16: =IF(I16<>"",(1+$M$10)^-(1+I16),"") -> 0.91673958 | Q16: 0 | R16: =IF(Q16<>"",1,"") -> 1 | S16: =IF(Q16<>"",(1+$M$10)^-(12*Q16),"") -> 1 | T16: =IFERROR(S16,"") -> 1
B17: =B16+1/12 -> 13.083333 | D17: =F17/E17 -> 3.55846e-05 | E17: =E16-(1/12)*F16 -> 999568.43 | F17: =E17-E18 -> 35.569242 | G17: =1-D17 -> 0.99996442 | I17: =IFERROR(IF(I16+1/12<$J$8,I16+1/12,""),"") -> 0.083333333 | J17: =IF(I17<>"",J16+1/12,"") -> 65.083333 | K17: =IFERROR(VLOOKUP(J17,$B$3:$F$1060,3,FALSE),"") -> 0.001665 | L17: =IF(I17<>"",1-K17,"") -> 0.998335 | M17: =IF(I17<>"",M16*L16,"") -> 0.98002 | N17: =IF(I17<>"",(1+$M$10)^-(1+I17),"") -> 0.91012242 | P17: M | Q17: =IFERROR(IF(Q16+1/12<$J$8,Q16+1/12,""),"") -> 0.083333333 | R17: =IF(Q17<>"",R16*L16,"") -> 0.98002 | S17: =IF(Q17<>"",(1+$M$10)^-(12*Q17),"") -> 0.91673958 | T17: =IFERROR(S17,"") -> 0.91673958
B18: =B17+1/12 -> 13.166667 | D18: =(B18-$B$16)*$D$16 -> 7.1166667e-05 | E18: =E16-(2/12)*F16 -> 999532.86 | F18: =E18-E19 -> 35.569242 | G18: =1-D18 -> 0.99992883 | I18: =IFERROR(IF(I17+1/12<$J$8,I17+1/12,""),"") -> 0.16666667 | J18: =IF(I18<>"",J17+1/12,"") -> 65.166667 | K18: =IFERROR(VLOOKUP(J18,$B$3:$F$1060,3,FALSE),"") -> 0.00333 | L18: =IF(I18<>"",1-K18,"") -> 0.99667 | M18: =IF(I18<>"",M17*L17,"") -> 0.97838827 | N18: =IF(I18<>"",(1+$M$10)^-(1+I18),"") -> 0.90355303 | P18: E | Q18: =IFERROR(IF(Q17+1/12<$J$8,Q17+1/12,""),"") -> 0.16666667 | R18: =IF(Q18<>"",R17*L17,"") -> 0.97838827 | S18: =IF(Q18<>"",(1+$M$10)^-(12*Q18),"") -> 0.84041146 | T18: =IFERROR(S18,"") -> 0.84041146
B19: =B18+1/12 -> 13.25 | D19: =(B19-$B$16)*$D$16 -> 0.00010675 | E19: =E16-(3/12)*F16 -> 999497.29 | F19: =E19-E20 -> 35.569242 | G19: =1-D19 -> 0.99989325 | I19: =IFERROR(IF(I18+1/12<$J$8,I18+1/12,""),"") -> 0.25 | J19: =IF(I19<>"",J18+1/12,"") -> 65.25 | K19: =IFERROR(VLOOKUP(J19,$B$3:$F$1060,3,FALSE),"") -> 0.004995 | L19: =IF(I19<>"",1-K19,"") -> 0.995005 | M19: =IF(I19<>"",M18*L18,"") -> 0.97513023 | N19: =IF(I19<>"",(1+$M$10)^-(1+I19),"") -> 0.89703105 | P19: N | Q19: =IFERROR(IF(Q18+1/12<$J$8,Q18+1/12,""),"") -> 0.25 | R19: =IF(Q19<>"",R18*L18,"") -> 0.97513023 | S19: =IF(Q19<>"",(1+$M$10)^-(12*Q19),"") -> 0.77043845 | T19: =IFERROR(S19,"") -> 0.77043845
B20: =B19+1/12 -> 13.333333 | D20: =(B20-$B$16)*$D$16 -> 0.00014233333 | E20: =E16-(4/12)*F16 -> 999461.72 | F20: =E20-E21 -> 35.569242 | G20: =1-D20 -> 0.99985767 | I20: =IFERROR(IF(I19+1/12<$J$8,I19+1/12,""),"") -> 0.33333333 | J20: =IF(I20<>"",J19+1/12,"") -> 65.333333 | K20: =IFERROR(VLOOKUP(J20,$B$3:$F$1060,3,FALSE),"") -> 0.00666 | L20: =IF(I20<>"",1-K20,"") -> 0.99334 | M20: =IF(I20<>"",M19*L19,"") -> 0.97025946 | N20: =IF(I20<>"",(1+$M$10)^-(1+I20),"") -> 0.89055616 | P20: S | Q20: =IFERROR(IF(Q19+1/12<$J$8,Q19+1/12,""),"") -> 0.33333333 | R20: =IF(Q20<>"",R19*L19,"") -> 0.97025946 | S20: =IF(Q20<>"",(1+$M$10)^-(12*Q20),"") -> 0.70629142 | T20: =IFERROR(S20,"") -> 0.70629142
B21: =B20+1/12 -> 13.416667 | D21: =(B21-$B$16)*$D$16 -> 0.00017791667 | E21: =E16-(5/12)*F16 -> 999426.15 | F21: =E21-E22 -> 35.569242 | G21: =1-D21 -> 0.99982208 | I21: =IFERROR(IF(I20+1/12<$J$8,I20+1/12,""),"") -> 0.41666667 | J21: =IF(I21<>"",J20+1/12,"") -> 65.416667 | K21: =IFERROR(VLOOKUP(J21,$B$3:$F$1060,3,FALSE),"") -> 0.008325 | L21: =IF(I21<>"",1-K21,"") -> 0.991675 | M21: =IF(I21<>"",M20*L20,"") -> 0.96379753 | N21: =IF(I21<>"",(1+$M$10)^-(1+I21),"") -> 0.88412799 | P21: U | Q21: =IFERROR(IF(Q20+1/12<$J$8,Q20+1/12,""),"") -> 0.41666667 | R21: =IF(Q21<>"",R20*L20,"") -> 0.96379753 | S21: =IF(Q21<>"",(1+$M$10)^-(12*Q21),"") -> 0.6474853 | T21: =IFERROR(S21,"") -> 0.6474853
B22: =B21+1/12 -> 13.5 | D22: =(B22-$B$16)*$D$16 -> 0.0002135 | E22: =E16-(6/12)*F16 -> 999390.58 | F22: =E22-E23 -> 35.569242 | G22: =1-D22 -> 0.9997865 | I22: =IFERROR(IF(I21+1/12<$J$8,I21+1/12,""),"") -> 0.5 | J22: =IF(I22<>"",J21+1/12,"") -> 65.5 | K22: =IFERROR(VLOOKUP(J22,$B$3:$F$1060,3,FALSE),"") -> 0.00999 | L22: =IF(I22<>"",1-K22,"") -> 0.99001 | M22: =IF(I22<>"",M21*L21,"") -> 0.95577392 | N22: =IF(I22<>"",(1+$M$10)^-(1+I22),"") -> 0.87774623 | P22: A | Q22: =IFERROR(IF(Q21+1/12<$J$8,Q21+1/12,""),"") -> 0.5 | R22: =IF(Q22<>"",R21*L21,"") -> 0.95577392 | S22: =IF(Q22<>"",(1+$M$10)^-(12*Q22),"") -> 0.5935754 | T22: =IFERROR(S22,"") -> 0.5935754
B23: =B22+1/12 -> 13.583333 | D23: =(B23-$B$16)*$D$16 -> 0.00024908333 | E23: =E16-(7/12)*F16 -> 999355.02 | F23: =E23-E24 -> 35.569242 | G23: =1-D23 -> 0.99975092 | I23: =IFERROR(IF(I22+1/12<$J$8,I22+1/12,""),"") -> 0.58333333 | J23: =IF(I23<>"",J22+1/12,"") -> 65.583333 | K23: =IFERROR(VLOOKUP(J23,$B$3:$F$1060,3,FALSE),"") -> 0.011655 | L23: =IF(I23<>"",1-K23,"") -> 0.988345 | M23: =IF(I23<>"",M22*L22,"") -> 0.94622573 | N23: =IF(I23<>"",(1+$M$10)^-(1+I23),"") -> 0.87141053 | P23: L | Q23: =IFERROR(IF(Q22+1/12<$J$8,Q22+1/12,""),"") -> 0.58333333 | R23: =IF(Q23<>"",R22*L22,"") -> 0.94622573 | S23: =IF(Q23<>"",(1+$M$10)^-(12*Q23),"") -> 0.54415406 | T23: =IFERROR(S23,"") -> 0.54415406
B24: =B23+1/12 -> 13.666667 | D24: =(B24-$B$16)*$D$16 -> 0.00028466667 | E24: =E16-(8/12)*F16 -> 999319.45 | F24: =E24-E25 -> 35.569242 | G24: =1-D24 -> 0.99971533 | I24: =IFERROR(IF(I23+1/12<$J$8,I23+1/12,""),"") -> 0.66666667 | J24: =IF(I24<>"",J23+1/12,"") -> 65.666667 | K24: =IFERROR(VLOOKUP(J24,$B$3:$F$1060,3,FALSE),"") -> 0.01332 | L24: =IF(I24<>"",1-K24,"") -> 0.98668 | M24: =IF(I24<>"",M23*L23,"") -> 0.93519747 | N24: =IF(I24<>"",(1+$M$10)^-(1+I24),"") -> 0.86512057 | P24: I | Q24: =IFERROR(IF(Q23+1/12<$J$8,Q23+1/12,""),"") -> 0.66666667 | R24: =IF(Q24<>"",R23*L23,"") -> 0.93519747 | S24: =IF(Q24<>"",(1+$M$10)^-(12*Q24),"") -> 0.49884757 | T24: =IFERROR(S24,"") -> 0.49884757
B25: =B24+1/12 -> 13.75 | D25: =(B25-$B$16)*$D$16 -> 0.00032025 | E25: =E16-(9/12)*F16 -> 999283.88 | F25: =E25-E26 -> 35.569242 | G25: =1-D25 -> 0.99967975 | I25: =IFERROR(IF(I24+1/12<$J$8,I24+1/12,""),"") -> 0.75 | J25: =IF(I25<>"",J24+1/12,"") -> 65.75 | K25: =IFERROR(VLOOKUP(J25,$B$3:$F$1060,3,FALSE),"") -> 0.014985 | L25: =IF(I25<>"",1-K25,"") -> 0.985015 | M25: =IF(I25<>"",M24*L24,"") -> 0.92274064 | N25: =IF(I25<>"",(1+$M$10)^-(1+I25),"") -> 0.858876 | P25: D | Q25: =IFERROR(IF(Q24+1/12<$J$8,Q24+1/12,""),"") -> 0.75 | R25: =IF(Q25<>"",R24*L24,"") -> 0.92274064 | S25: =IF(Q25<>"",(1+$M$10)^-(12*Q25),"") -> 0.45731331 | T25: =IFERROR(S25,"") -> 0.45731331
B26: =B25+1/12 -> 13.833333 | D26: =(B26-$B$16)*$D$16 -> 0.00035583333 | E26: =E16-(10/12)*F16 -> 999248.31 | F26: =E26-E27 -> 35.569242 | G26: =1-D26 -> 0.99964417 | I26: =IFERROR(IF(I25+1/12<$J$8,I25+1/12,""),"") -> 0.83333333 | J26: =IF(I26<>"",J25+1/12,"") -> 65.833333 | K26: =IFERROR(VLOOKUP(J26,$B$3:$F$1060,3,FALSE),"") -> 0.01665 | L26: =IF(I26<>"",1-K26,"") -> 0.98335 | M26: =IF(I26<>"",M25*L25,"") -> 0.90891337 | N26: =IF(I26<>"",(1+$M$10)^-(1+I26),"") -> 0.85267651 | P26: A | Q26: =IFERROR(IF(Q25+1/12<$J$8,Q25+1/12,""),"") -> 0.83333333 | R26: =IF(Q26<>"",R25*L25,"") -> 0.90891337 | S26: =IF(Q26<>"",(1+$M$10)^-(12*Q26),"") -> 0.41923721 | T26: =IFERROR(S26,"") -> 0.41923721
B27: =B26+1/12 -> 13.916667 | D27: =(B27-$B$16)*$D$16 -> 0.00039141667 | E27: =E16-(11/12)*F16 -> 999212.74 | F27: =E27-E28 -> 35.569242 | G27: =1-D27 -> 0.99960858 | I27: =IFERROR(IF(I26+1/12<$J$8,I26+1/12,""),"") -> 0.91666667 | J27: =IF(I27<>"",J26+1/12,"") -> 65.916667 | K27: =IFERROR(VLOOKUP(J27,$B$3:$F$1060,3,FALSE),"") -> 0.018315 | L27: =IF(I27<>"",1-K27,"") -> 0.981685 | M27: =IF(I27<>"",M26*L26,"") -> 0.89377997 | N27: =IF(I27<>"",(1+$M$10)^-(1+I27),"") -> 0.84652177 | P27: D | Q27: =IFERROR(IF(Q26+1/12<$J$8,Q26+1/12,""),"") -> 0.91666667 | R27: =IF(Q27<>"",R26*L26,"") -> 0.89377997 | S27: =IF(Q27<>"",(1+$M$10)^-(12*Q27),"") -> 0.38433135 | T27: =IFERROR(S27,"") -> 0.38433135
B28: 14 | C28: 0.46 | D28: =C28/1000 -> 0.00046 | E28: =E16-F16 -> 999177.17 | F28: =D28*E28 -> 459.6215 | G28: =1-D28 -> 0.99954 | I28: =IFERROR(IF(I27+1/12<$J$8,I27+1/12,""),"") -> 1 | J28: =IF(I28<>"",J27+1/12,"") -> 66 | K28: =IFERROR(VLOOKUP(J28,$B$3:$F$1060,3,TRUE),"") -> 0.018315 | L28: =IF(I28<>"",1-K28,"") -> 0.981685 | M28: =IF(I28<>"",M27*L27,"") -> 0.87741039 | N28: =IF(I28<>"",(1+$M$10)^-(1+I28),"") -> 0.84041146 | P28: E | Q28: =IFERROR(IF(Q27+1/12<$J$8,Q27+1/12,""),"") -> 1 | R28: =IF(Q28<>"",R27*L27,"") -> 0.87741039 | S28: =IF(Q28<>"",(1+$M$10)^-(12*Q28),"") -> 0.35233176 | T28: =IFERROR(S28,"") -> 0.35233176
B29: =B28+1/12 -> 14.083333 | D29: =(B29-$B$28)*$D$28 -> 3.8333333e-05 | E29: =E28-(1/12)*F28 -> 999138.87 | F29: =E29-E30 -> 38.301791 | G29: =1-D29 -> 0.99996167 | I29: =IFERROR(IF(I28+1/12<$J$8,I28+1/12,""),"") -> 1.0833333 | J29: =IF(I29<>"",J28+1/12,"") -> 66.083333 | K29: =IFERROR(VLOOKUP(J29,$B$3:$F$1060,3,TRUE),"") -> 0.02149 | L29: =IF(I29<>"",1-K29,"") -> 0.97851 | M29: =IF(I29<>"",M28*L28,"") -> 0.86134062 | N29: =IF(I29<>"",(1+$M$10)^-(1+I29),"") -> 0.83434525 | P29: S | Q29: =IFERROR(IF(Q28+1/12<$J$8,Q28+1/12,""),"") -> 1.0833333 | R29: =IF(Q29<>"",R28*L28,"") -> 0.86134062 | S29: =IF(Q29<>"",(1+$M$10)^-(12*Q29),"") -> 0.32299647 | T29: =IFERROR(S29,"") -> 0.32299647
B30: =B29+1/12 -> 14.166667 | D30: =(B30-$B$28)*$D$28 -> 7.6666667e-05 | E30: =E28-(2/12)*F28 -> 999100.57 | F30: =E30-E31 -> 38.301791 | G30: =1-D30 -> 0.99992333 | I30: =IFERROR(IF(I29+1/12<$J$8,I29+1/12,""),"") -> 1.1666667 | J30: =IF(I30<>"",J29+1/12,"") -> 66.166667 | K30: =IFERROR(VLOOKUP(J30,$B$3:$F$1060,3,TRUE),"") -> 0.0017908333 | L30: =IF(I30<>"",1-K30,"") -> 0.99820917 | M30: =IF(I30<>"",M29*L29,"") -> 0.84283041 | N30: =IF(I30<>"",(1+$M$10)^-(1+I30),"") -> 0.82832283 | Q30: =IFERROR(IF(Q29+1/12<$J$8,Q29+1/12,""),"") -> 1.1666667 | R30: =IF(Q30<>"",R29*L29,"") -> 0.84283041 | S30: =IF(Q30<>"",(1+$M$10)^-(12*Q30),"") -> 0.29610365 | T30: =IFERROR(S30,"") -> 0.29610365
B31: =B30+1/12 -> 14.25 | D31: =(B31-$B$28)*$D$28 -> 0.000115 | E31: =E28-(3/12)*F28 -> 999062.26 | F31: =E31-E32 -> 38.301791 | G31: =1-D31 -> 0.999885 | I31: =IFERROR(IF(I30+1/12<$J$8,I30+1/12,""),"") -> 1.25 | J31: =IF(I31<>"",J30+1/12,"") -> 66.25 | K31: =IFERROR(VLOOKUP(J31,$B$3:$F$1060,3,TRUE),"") -> 0.0035816667 | L31: =IF(I31<>"",1-K31,"") -> 0.99641833 | M31: =IF(I31<>"",M30*L30,"") -> 0.84132104 | N31: =IF(I31<>"",(1+$M$10)^-(1+I31),"") -> 0.82234387 | P31: G | Q31: =IFERROR(IF(Q30+1/12<$J$8,Q30+1/12,""),"") -> 1.25 | R31: =IF(Q31<>"",R30*L30,"") -> 0.84132104 | S31: =IF(Q31<>"",(1+$M$10)^-(12*Q31),"") -> 0.27144993 | T31: =IFERROR(S31,"") -> 0.27144993
B32: =B31+1/12 -> 14.333333 | D32: =(B32-$B$28)*$D$28 -> 0.00015333333 | E32: =E28-(4/12)*F28 -> 999023.96 | F32: =E32-E33 -> 38.301791 | G32: =1-D32 -> 0.99984667 | I32: =IFERROR(IF(I31+1/12<$J$8,I31+1/12,""),"") -> 1.3333333 | J32: =IF(I32<>"",J31+1/12,"") -> 66.333333 | K32: =IFERROR(VLOOKUP(J32,$B$3:$F$1060,3,TRUE),"") -> 0.0053725 | L32: =IF(I32<>"",1-K32,"") -> 0.9946275 | M32: =IF(I32<>"",M31*L31,"") -> 0.83830771 | N32: =IF(I32<>"",(1+$M$10)^-(1+I32),"") -> 0.81640808 | P32: A | Q32: =IFERROR(IF(Q31+1/12<$J$8,Q31+1/12,""),"") -> 1.3333333 | R32: =IF(Q32<>"",R31*L31,"") -> 0.83830771 | S32: =IF(Q32<>"",(1+$M$10)^-(12*Q32),"") -> 0.2488489 | T32: =IFERROR(S32,"") -> 0.2488489
B33: =B32+1/12 -> 14.416667 | D33: =(B33-$B$28)*$D$28 -> 0.00019166667 | E33: =E28-(5/12)*F28 -> 998985.66 | F33: =E33-E34 -> 38.301791 | G33: =1-D33 -> 0.99980833 | I33: =IFERROR(IF(I32+1/12<$J$8,I32+1/12,""),"") -> 1.4166667 | J33: =IF(I33<>"",J32+1/12,"") -> 66.416667 | K33: =IFERROR(VLOOKUP(J33,$B$3:$F$1060,3,TRUE),"") -> 0.0071633333 | L33: =IF(I33<>"",1-K33,"") -> 0.99283667 | M33: =IF(I33<>"",M32*L32,"") -> 0.8338039 | N33: =IF(I33<>"",(1+$M$10)^-(1+I33),"") -> 0.81051513 | P33: R | Q33: =IFERROR(IF(Q32+1/12<$J$8,Q32+1/12,""),"") -> 1.4166667 | R33: =IF(Q33<>"",R32*L32,"") -> 0.8338039 | S33: =IF(Q33<>"",(1+$M$10)^-(12*Q33),"") -> 0.22812963 | T33: =IFERROR(S33,"") -> 0.22812963
B34: =B33+1/12 -> 14.5 | D34: =(B34-$B$28)*$D$28 -> 0.00023 | E34: =E28-(6/12)*F28 -> 998947.36 | F34: =E34-E35 -> 38.301791 | G34: =1-D34 -> 0.99977 | I34: =IFERROR(IF(I33+1/12<$J$8,I33+1/12,""),"") -> 1.5 | J34: =IF(I34<>"",J33+1/12,"") -> 66.5 | K34: =IFERROR(VLOOKUP(J34,$B$3:$F$1060,3,TRUE),"") -> 0.0089541667 | L34: =IF(I34<>"",1-K34,"") -> 0.99104583 | M34: =IF(I34<>"",M33*L33,"") -> 0.82783108 | N34: =IF(I34<>"",(1+$M$10)^-(1+I34),"") -> 0.80466471 | P34: A | Q34: =IFERROR(IF(Q33+1/12<$J$8,Q33+1/12,""),"") -> 1.5 | R34: =IF(Q34<>"",R33*L33,"") -> 0.82783108 | S34: =IF(Q34<>"",(1+$M$10)^-(12*Q34),"") -> 0.20913546 | T34: =IFERROR(S34,"") -> 0.20913546
B35: =B34+1/12 -> 14.583333 | D35: =(B35-$B$28)*$D$28 -> 0.00026833333 | E35: =E28-(7/12)*F28 -> 998909.06 | F35: =E35-E36 -> 38.301791 | G35: =1-D35 -> 0.99973167 | I35: =IFERROR(IF(I34+1/12<$J$8,I34+1/12,""),"") -> 1.5833333 | J35: =IF(I35<>"",J34+1/12,"") -> 66.583333 | K35: =IFERROR(VLOOKUP(J35,$B$3:$F$1060,3,TRUE),"") -> 0.010745 | L35: =IF(I35<>"",1-K35,"") -> 0.989255 | M35: =IF(I35<>"",M34*L34,"") -> 0.82041854 | N35: =IF(I35<>"",(1+$M$10)^-(1+I35),"") -> 0.79885653 | P35: N | Q35: =IFERROR(IF(Q34+1/12<$J$8,Q34+1/12,""),"") -> 1.5833333 | R35: =IF(Q35<>"",R34*L34,"") -> 0.82041854 | S35: =IF(Q35<>"",(1+$M$10)^-(12*Q35),"") -> 0.19172276 | T35: =IFERROR(S35,"") -> 0.19172276
B36: =B35+1/12 -> 14.666667 | D36: =(B36-$B$28)*$D$28 -> 0.00030666667 | E36: =E28-(8/12)*F28 -> 998870.75 | F36: =E36-E37 -> 38.301791 | G36: =1-D36 -> 0.99969333 | I36: =IFERROR(IF(I35+1/12<$J$8,I35+1/12,""),"") -> 1.6666667 | J36: =IF(I36<>"",J35+1/12,"") -> 66.666667 | K36: =IFERROR(VLOOKUP(J36,$B$3:$F$1060,3,TRUE),"") -> 0.012535833 | L36: =IF(I36<>"",1-K36,"") -> 0.98746417 | M36: =IF(I36<>"",M35*L35,"") -> 0.81160315 | N36: =IF(I36<>"",(1+$M$10)^-(1+I36),"") -> 0.79309027 | P36: T | Q36: =IFERROR(IF(Q35+1/12<$J$8,Q35+1/12,""),"") -> 1.6666667 | R36: =IF(Q36<>"",R35*L35,"") -> 0.81160315 | S36: =IF(Q36<>"",(1+$M$10)^-(12*Q36),"") -> 0.17575984 | T36: =IFERROR(S36,"") -> 0.17575984
B37: =B36+1/12 -> 14.75 | D37: =(B37-$B$28)*$D$28 -> 0.000345 | E37: =E28-(9/12)*F28 -> 998832.45 | F37: =E37-E38 -> 38.301791 | G37: =1-D37 -> 0.999655 | I37: =IFERROR(IF(I36+1/12<$J$8,I36+1/12,""),"") -> 1.75 | J37: =IF(I37<>"",J36+1/12,"") -> 66.75 | K37: =IFERROR(VLOOKUP(J37,$B$3:$F$1060,3,TRUE),"") -> 0.014326667 | L37: =IF(I37<>"",1-K37,"") -> 0.98567333 | M37: =IF(I37<>"",M36*L36,"") -> 0.80142903 | N37: =IF(I37<>"",(1+$M$10)^-(1+I37),"") -> 0.78736563 | P37: I | Q37: =IFERROR(IF(Q36+1/12<$J$8,Q36+1/12,""),"") -> 1.75 | R37: =IF(Q37<>"",R36*L36,"") -> 0.80142903 | S37: =IF(Q37<>"",(1+$M$10)^-(12*Q37),"") -> 0.161126 | T37: =IFERROR(S37,"") -> 0.161126
B38: =B37+1/12 -> 14.833333 | D38: =(B38-$B$28)*$D$28 -> 0.00038333333 | E38: =E28-(10/12)*F28 -> 998794.15 | F38: =E38-E39 -> 38.301791 | G38: =1-D38 -> 0.99961667 | I38: =IFERROR(IF(I37+1/12<$J$8,I37+1/12,""),"") -> 1.8333333 | J38: =IF(I38<>"",J37+1/12,"") -> 66.833333 | K38: =IFERROR(VLOOKUP(J38,$B$3:$F$1060,3,TRUE),"") -> 0.0161175 | L38: =IF(I38<>"",1-K38,"") -> 0.9838825 | M38: =IF(I38<>"",M37*L37,"") -> 0.78994722 | N38: =IF(I38<>"",(1+$M$10)^-(1+I38),"") -> 0.78168231 | P38: Z | Q38: =IFERROR(IF(Q37+1/12<$J$8,Q37+1/12,""),"") -> 1.8333333 | R38: =IF(Q38<>"",R37*L37,"") -> 0.78994722 | S38: =IF(Q38<>"",(1+$M$10)^-(12*Q38),"") -> 0.14771058 | T38: =IFERROR(S38,"") -> 0.14771058
B39: =B38+1/12 -> 14.916667 | D39: =(B39-$B$28)*$D$28 -> 0.00042166667 | E39: =E28-(11/12)*F28 -> 998755.85 | F39: =E39-E40 -> 38.301791 | G39: =1-D39 -> 0.99957833 | I39: =IFERROR(IF(I38+1/12<$J$8,I38+1/12,""),"") -> 1.9166667 | J39: =IF(I39<>"",J38+1/12,"") -> 66.916667 | K39: =IFERROR(VLOOKUP(J39,$B$3:$F$1060,3,TRUE),"") -> 0.017908333 | L39: =IF(I39<>"",1-K39,"") -> 0.98209167 | M39: =IF(I39<>"",M38*L38,"") -> 0.77721524 | N39: =IF(I39<>"",(1+$M$10)^-(1+I39),"") -> 0.77604002 | P39: A | Q39: =IFERROR(IF(Q38+1/12<$J$8,Q38+1/12,""),"") -> 1.9166667 | R39: =IF(Q39<>"",R38*L38,"") -> 0.77721524 | S39: =IF(Q39<>"",(1+$M$10)^-(12*Q39),"") -> 0.13541214 | T39: =IFERROR(S39,"") -> 0.13541214
B40: 15 | C40: 0.495 | D40: =C40/1000 -> 0.000495 | E40: =E28-F28 -> 998717.55 | F40: =D40*E40 -> 494.36519 | G40: =1-D40 -> 0.999505 | I40: =IFERROR(IF(I39+1/12<$J$8,I39+1/12,""),"") -> 2 | J40: =IF(I40<>"",J39+1/12,"") -> 67 | K40: =IFERROR(VLOOKUP(J40,$B$3:$F$1060,3,TRUE),"") -> 0.019699167 | L40: =IF(I40<>"",1-K40,"") -> 0.98030083 | M40: =IF(I40<>"",M39*L39,"") -> 0.76329662 | N40: =IF(I40<>"",(1+$M$10)^-(1+I40),"") -> 0.77043845 | P40: D | Q40: =IFERROR(IF(Q39+1/12<$J$8,Q39+1/12,""),"") -> 2 | R40: =IF(Q40<>"",R39*L39,"") -> 0.76329662 | S40: =IF(Q40<>"",(1+$M$10)^-(12*Q40),"") -> 0.12413767 | T40: =IFERROR(S40,"") -> 0.12413767
B41: =B40+1/12 -> 15.083333 | D41: =(B41-$B$40)*$D$40 -> 4.125e-05 | E41: =E40-(1/12)*F40 -> 998676.35 | F41: =E41-E42 -> 41.197099 | G41: =1-D41 -> 0.99995875 | I41: =IFERROR(IF(I40+1/12<$J$8,I40+1/12,""),"") -> 2.0833333 | J41: =IF(I41<>"",J40+1/12,"") -> 67.083333 | K41: =IFERROR(VLOOKUP(J41,$B$3:$F$1060,3,TRUE),"") -> 0.023111 | L41: =IF(I41<>"",1-K41,"") -> 0.976889 | M41: =IF(I41<>"",M40*L40,"") -> 0.74826031 | N41: =IF(I41<>"",(1+$M$10)^-(1+I41),"") -> 0.76487731 | P41: A | Q41: =IFERROR(IF(Q40+1/12<$J$8,Q40+1/12,""),"") -> 2.0833333 | R41: =IF(Q41<>"",R40*L40,"") -> 0.74826031 | S41: =IF(Q41<>"",(1+$M$10)^-(12*Q41),"") -> 0.11380191 | T41: =IFERROR(S41,"") -> 0.11380191
B42: =B41+1/12 -> 15.166667 | D42: =(B42-$B$40)*$D$40 -> 8.25e-05 | E42: =E40-(2/12)*F40 -> 998635.15 | F42: =E42-E43 -> 41.197099 | G42: =1-D42 -> 0.9999175 | I42: =IFERROR(IF(I41+1/12<$J$8,I41+1/12,""),"") -> 2.1666667 | J42: =IF(I42<>"",J41+1/12,"") -> 67.166667 | K42: =IFERROR(VLOOKUP(J42,$B$3:$F$1060,3,TRUE),"") -> 0.0019259167 | L42: =IF(I42<>"",1-K42,"") -> 0.99807408 | M42: =IF(I42<>"",M41*L41,"") -> 0.73096726 | N42: =IF(I42<>"",(1+$M$10)^-(1+I42),"") -> 0.75935632 | P42: S | Q42: =IFERROR(IF(Q41+1/12<$J$8,Q41+1/12,""),"") -> 2.1666667 | R42: =IF(Q42<>"",R41*L41,"") -> 0.73096726 | S42: =IF(Q42<>"",(1+$M$10)^-(12*Q42),"") -> 0.10432672 | T42: =IFERROR(S42,"") -> 0.10432672
...

Sheet Anual
K1: Seguro de Rentas Vitalicias | N1: Calculo de Renta Anual
G2: Moneda | H2: Pesos
B3: Edad | C3: CNSF 2000-I | D3: qx
B4: 12 | C4: 0.396 | D4: =C4/1000 -> 0.000396 | G4: Edad Contratación | H4: ='Prima Riesgo'!C6 -> 65 | J4: Valor Anualidad | K4: =Q12 -> 8.3988896 | M4: ¿Cuánto pagarás de prima única? | N4: ='Prima Riesgo'!I6 -> 1000000 | P4: ¿Cuánto quieres recibir de Renta Anual? | Q4: ='Prima Riesgo'!L8 -> 7500
B5: 13 | C5: 0.427 | D5: =C5/1000 -> 0.000427
B6: 14 | C6: 0.46 | D6: =C6/1000 -> 0.00046 | G6: Plazo del Seguro (w-x) | H6: =B92-H4 -> 35 | J6: Tasa interes técnico | K6: ='Prima Riesgo'!F8 -> 0.0947 | M6: Recibirás de Renta Anual: | N6: =N4/Q12 -> 119063.36 | P6: Debes pagar como Prima Única: | Q6: =Q4*Q12 -> 62991.672
B7: 15 | C7: 0.495 | D7: =C7/1000 -> 0.000495
B8: 16 | C8: 0.533 | D8: =C8/1000 -> 0.000533
B9: 17 | C9: 0.575 | D9: =C9/1000 -> 0.000575 | J9: =IF(K8>K4,"El plazo de pago de primas es incorrecto","")
B10: 18 | C10: 0.619 | D10: =C10/1000 -> 0.000619
B11: 19 | C11: 0.667 | D11: =C11/1000 -> 0.000667
B12: 20 | C12: 0.718 | D12: =C12/1000 -> 0.000718 | P12: suma flujo anualidad | Q12: =SUM(Q14:Q104) -> 8.3988896
B13: 21 | C13: 0.773 | D13: =C13/1000 -> 0.000773 | F13: t | G13: (x) | H13: qx+t | I13: px | J13: tpx | K13: V^t | N13: s | O13: spx | P13: V^s | Q13: Flujo Anualidad
B14: 22 | C14: 0.833 | D14: =C14/1000 -> 0.000833 | F14: 0 | G14: =H4 -> 65 | H14: =IFERROR(VLOOKUP(G14,$B$3:$D$92,3,FALSE),"") -> 0.01998 | I14: =IF(F14<>"",1-H14,"") -> 0.98002 | J14: =IF(F14<>"",1,"") -> 1 | K14: =IF(F14<>"",(1+$K$6)^-(1+F14),"") -> 0.91349228 | N14: 0 | O14: =IF(N14<>"",1,"") -> 1 | P14: =IF(N14<>"",(1+$K$6)^-(N14),"") -> 1 | Q14: =IFERROR(P14*O14,"") -> 1
B15: 23 | C15: 0.897 | D15: =C15/1000 -> 0.000897 | F15: =IFERROR(IF(F14+1<$H$6,F14+1,""),"") -> 1 | G15: =IF(F15<>"",G14+1,"") -> 66 | H15: =IFERROR(VLOOKUP(G15,$B$3:$D$92,3,FALSE),"") -> 0.02149 | I15: =IF(F15<>"",1-H15,"") -> 0.97851 | J15: =IF(F15<>"",J14*I14,"") -> 0.98002 | K15: =IF(F15<>"",(1+$K$6)^-(1+F15),"") -> 0.83446815 | N15: =IFERROR(IF(N14+1<$H$6,N14+1,""),"") -> 1 | O15: =IF(N15<>"",O14*I14,"") -> 0.98002 | P15: =IF(N15<>"",(1+$K$6)^-(N15),"") -> 0.91349228 | Q15: =IFERROR(P15*O15,"") -> 0.89524071
B16: 24 | C16: 0.966 | D16: =C16/1000 -> 0.000966 | F16: =IFERROR(IF(F15+1<$H$6,F15+1,""),"") -> 2 | G16: =IF(F16<>"",G15+1,"") -> 67 | H16: =IFERROR(VLOOKUP(G16,$B$3:$D$92,3,FALSE),"") -> 0.023111 | I16: =IF(F16<>"",1-H16,"") -> 0.976889 | J16: =IF(F16<>"",J15*I15,"") -> 0.95895937 | K16: =IF(F16<>"",(1+$K$6)^-(1+F16),"") -> 0.76228021 | N16: =IFERROR(IF(N15+1<$H$6,N15+1,""),"") -> 2 | O16: =IF(N16<>"",O15*I15,"") -> 0.95895937 | P16: =IF(N16<>"",(1+$K$6)^-(N16),"") -> 0.83446815 | Q16: =IFERROR(P16*O16,"") -> 0.80022105
B17: 25 | C17: 1.041 | D17: =C17/1000 -> 0.001041 | F17: =IFERROR(IF(F16+1<$H$6,F16+1,""),"") -> 3 | G17: =IF(F17<>"",G16+1,"") -> 68 | H17: =IFERROR(VLOOKUP(G17,$B$3:$D$92,3,FALSE),"") -> 0.024851 | I17: =IF(F17<>"",1-H17,"") -> 0.975149 | J17: =IF(F17<>"",J16*I16,"") -> 0.93679686 | K17: =IF(F17<>"",(1+$K$6)^-(1+F17),"") -> 0.69633709 | N17: =IFERROR(IF(N16+1<$H$6,N16+1,""),"") -> 3 | O17: =IF(N17<>"",O16*I16,"") -> 0.93679686 | P17: =IF(N17<>"",(1+$K$6)^-(N17),"") -> 0.76228021 | Q17: =IFERROR(P17*O17,"") -> 0.71410171
B18: 26 | C18: 1.121 | D18: =C18/1000 -> 0.001121 | F18: =IFERROR(IF(F17+1<$H$6,F17+1,""),"") -> 4 | G18: =IF(F18<>"",G17+1,"") -> 69 | H18: =IFERROR(VLOOKUP(G18,$B$3:$D$92,3,FALSE),"") -> 0.02672 | I18: =IF(F18<>"",1-H18,"") -> 0.97328 | J18: =IF(F18<>"",J17*I17,"") -> 0.91351652 | K18: =IF(F18<>"",(1+$K$6)^-(1+F18),"") -> 0.63609856 | N18: =IFERROR(IF(N17+1<$H$6,N17+1,""),"") -> 4 | O18: =IF(N18<>"",O17*I17,"") -> 0.91351652 | P18: =IF(N18<>"",(1+$K$6)^-(N18),"") -> 0.69633709 | Q18: =IFERROR(P18*O18,"") -> 0.63611544
B19: 27 | C19: 1.207 | D19: =C19/1000 -> 0.001207 | F19: =IFERROR(IF(F18+1<$H$6,F18+1,""),"") -> 5 | G19: =IF(F19<>"",G18+1,"") -> 70 | H19: =IFERROR(VLOOKUP(G19,$B$3:$D$92,3,FALSE),"") -> 0.028724 | I19: =IF(F19<>"",1-H19,"") -> 0.971276 | J19: =IF(F19<>"",J18*I18,"") -> 0.88910736 | K19: =IF(F19<>"",(1+$K$6)^-(1+F19),"") -> 0.58107112 | N19: =IFERROR(IF(N18+1<$H$6,N18+1,""),"") -> 5 | O19: =IF(N19<>"",O18*I18,"") -> 0.88910736 | P19: =IF(N19<>"",(1+$K$6)^-(N19),"") -> 0.63609856 | Q19: =IFERROR(P19*O19,"") -> 0.56555991
B20: 28 | C20: 1.3 | D20: =C20/1000 -> 0.0013 | F20: =IFERROR(IF(F19+1<$H$6,F19+1,""),"") -> 6 | G20: =IF(F20<>"",G19+1,"") -> 71 | H20: =IFERROR(VLOOKUP(G20,$B$3:$D$92,3,FALSE),"") -> 0.030874 | I20: =IF(F20<>"",1-H20,"") -> 0.969126 | J20: =IF(F20<>"",J19*I19,"") -> 0.86356864 | K20: =IF(F20<>"",(1+$K$6)^-(1+F20),"") -> 0.53080398 | N20: =IFERROR(IF(N19+1<$H$6,N19+1,""),"") -> 6 | O20: =IF(N20<>"",O19*I19,"") -> 0.86356864 | P20: =IF(N20<>"",(1+$K$6)^-(N20),"") -> 0.58107112 | Q20: =IFERROR(P20*O20,"") -> 0.5017948
B21: 29 | C21: 1.4 | D21: =C21/1000 -> 0.0014 | F21: =IFERROR(IF(F20+1<$H$6,F20+1,""),"") -> 7 | G21: =IF(F21<>"",G20+1,"") -> 72 | H21: =IFERROR(VLOOKUP(G21,$B$3:$D$92,3,FALSE),"") -> 0.03318 | I21: =IF(F21<>"",1-H21,"") -> 0.96682 | J21: =IF(F21<>"",J20*I20,"") -> 0.83690682 | K21: =IF(F21<>"",(1+$K$6)^-(1+F21),"") -> 0.48488534 | N21: =IFERROR(IF(N20+1<$H$6,N20+1,""),"") -> 7 | O21: =IF(N21<>"",O20*I20,"") -> 0.83690682 | P21: =IF(N21<>"",(1+$K$6)^-(N21),"") -> 0.53080398 | Q21: =IFERROR(P21*O21,"") -> 0.44423347
B22: 30 | C22: 1.508 | D22: =C22/1000 -> 0.001508 | F22: =IFERROR(IF(F21+1<$H$6,F21+1,""),"") -> 8 | G22: =IF(F22<>"",G21+1,"") -> 73 | H22: =IFERROR(VLOOKUP(G22,$B$3:$D$92,3,FALSE),"") -> 0.035651 | I22: =IF(F22<>"",1-H22,"") -> 0.964349 | J22: =IF(F22<>"",J21*I21,"") -> 0.80913825 | K22: =IF(F22<>"",(1+$K$6)^-(1+F22),"") -> 0.44293902 | N22: =IFERROR(IF(N21+1<$H$6,N21+1,""),"") -> 8 | O22: =IF(N22<>"",O21*I21,"") -> 0.80913825 | P22: =IF(N22<>"",(1+$K$6)^-(N22),"") -> 0.48488534 | Q22: =IFERROR(P22*O22,"") -> 0.39233928
B23: 31 | C23: 1.624 | D23: =C23/1000 -> 0.001624 | F23: =IFERROR(IF(F22+1<$H$6,F22+1,""),"") -> 9 | G23: =IF(F23<>"",G22+1,"") -> 74 | H23: =IFERROR(VLOOKUP(G23,$B$3:$D$92,3,FALSE),"") -> 0.0383 | I23: =IF(F23<>"",1-H23,"") -> 0.9617 | J23: =IF(F23<>"",J22*I22,"") -> 0.78029167 | K23: =IF(F23<>"",(1+$K$6)^-(1+F23),"") -> 0.40462137 | N23: =IFERROR(IF(N22+1<$H$6,N22+1,""),"") -> 9 | O23: =IF(N23<>"",O22*I22,"") -> 0.78029167 | P23: =IF(N23<>"",(1+$K$6)^-(N23),"") -> 0.44293902 | Q23: =IFERROR(P23*O23,"") -> 0.34562162
B24: 32 | C24: 1.749 | D24: =C24/1000 -> 0.001749 | F24: =IFERROR(IF(F23+1<$H$6,F23+1,""),"") -> 10 | G24: =IF(F24<>"",G23+1,"") -> 75 | H24: =IFERROR(VLOOKUP(G24,$B$3:$D$92,3,FALSE),"") -> 0.041136 | I24: =IF(F24<>"",1-H24,"") -> 0.958864 | J24: =IF(F24<>"",J23*I23,"") -> 0.75040649 | K24: =IF(F24<>"",(1+$K$6)^-(1+F24),"") -> 0.3696185 | N24: =IFERROR(IF(N23+1<$H$6,N23+1,""),"") -> 10 | O24: =IF(N24<>"",O23*I23,"") -> 0.75040649 | P24: =IF(N24<>"",(1+$K$6)^-(N24),"") -> 0.40462137 | Q24: =IFERROR(P24*O24,"") -> 0.30363051
B25: 33 | C25: 1.884 | D25: =C25/1000 -> 0.001884 | F25: =IFERROR(IF(F24+1<$H$6,F24+1,""),"") -> 11 | G25: =IF(F25<>"",G24+1,"") -> 76 | H25: =IFERROR(VLOOKUP(G25,$B$3:$D$92,3,FALSE),"") -> 0.044174 | I25: =IF(F25<>"",1-H25,"") -> 0.955826 | J25: =IF(F25<>"",J24*I24,"") -> 0.71953777 | K25: =IF(F25<>"",(1+$K$6)^-(1+F25),"") -> 0.33764365 | N25: =IFERROR(IF(N24+1<$H$6,N24+1,""),"") -> 11 | O25: =IF(N25<>"",O24*I24,"") -> 0.71953777 | P25: =IF(N25<>"",(1+$K$6)^-(N25),"") -> 0.3696185 | Q25: =IFERROR(P25*O25,"") -> 0.26595447
B26: 34 | C26: 2.029 | D26: =C26/1000 -> 0.002029 | F26: =IFERROR(IF(F25+1<$H$6,F25+1,""),"") -> 12 | G26: =IF(F26<>"",G25+1,"") -> 77 | H26: =IFERROR(VLOOKUP(G26,$B$3:$D$92,3,FALSE),"") -> 0.047424 | I26: =IF(F26<>"",1-H26,"") -> 0.952576 | J26: =IF(F26<>"",J25*I25,"") -> 0.68775291 | K26: =IF(F26<>"",(1+$K$6)^-(1+F26),"") -> 0.30843487 | N26: =IFERROR(IF(N25+1<$H$6,N25+1,""),"") -> 12 | O26: =IF(N26<>"",O25*I25,"") -> 0.68775291 | P26: =IF(N26<>"",(1+$K$6)^-(N26),"") -> 0.33764365 | Q26: =IFERROR(P26*O26,"") -> 0.2322154
... B92: 100 | C92: 1000 | D92: =C92/1000 -> 1 | F92: =IFERROR(IF(F91+1<$H$6,F91+1,""),"") | G92: =IF(F92<>"",G91+1,"") | H92: =IFERROR(VLOOKUP(G92,$B$3:$D$92,3,FALSE),"") | I92: =IF(F92<>"",1-H92,"") | J92: =IF(F92<>"",J91*I91,"") | K92: =IF(F92<>"",(1+$K$6)^-(1+F92),"") | N92: =IFERROR(IF(N91+1<$H$6,N91+1,""),"") | O92: =IF(N92<>"",O91*I91,"") | P92: =IF(N92<>"",(1+$K$6)^-(N92),"") | Q92: =IFERROR(P92*O92,"")
F93: =IFERROR(IF(F92+1<$H$6,F92+1,""),"") | G93: =IF(F93<>"",G92+1,"") | H93: =IFERROR(VLOOKUP(G93,$B$3:$D$92,3,FALSE),"") | I93: =IF(F93<>"",1-H93,"") | J93: =IF(F93<>"",J92*I92,"") | K93: =IF(F93<>"",(1+$K$6)^-(1+F93),"") | N93: =IFERROR(IF(N92+1<$H$6,N92+1,""),"") | O93: =IF(N93<>"",O92*I92,"") | P93: =IF(N93<>"",(1+$K$6)^-(N93),"") | Q93: =IFERROR(P93*O93,"")
F94: =IFERROR(IF(F93+1<$H$6,F93+1,""),"") | G94: =IF(F94<>"",G93+1,"") | H94: =IFERROR(VLOOKUP(G94,$B$3:$D$92,3,FALSE),"") | I94: =IF(F94<>"",1-H94,"") | J94: =IF(F94<>"",J93*I93,"") | K94: =IF(F94<>"",(1+$K$6)^-(1+F94),"") | N94: =IFERROR(IF(N93+1<$H$6,N93+1,""),"") | O94: =IF(N94<>"",O93*I93,"") | P94: =IF(N94<>"",(1+$K$6)^-(N94),"") | Q94: =IFERROR(P94*O94,"")
F95: =IFERROR(IF(F94+1<$H$6,F94+1,""),"") | G95: =IF(F95<>"",G94+1,"") | H95: =IFERROR(VLOOKUP(G95,$B$3:$D$92,3,FALSE),"") | I95: =IF(F95<>"",1-H95,"") | J95: =IF(F95<>"",J94*I94,"") | K95: =IF(F95<>"",(1+$K$6)^-(1+F95),"") | N95: =IFERROR(IF(N94+1<$H$6,N94+1,""),"") | O95: =IF(N95<>"",O94*I94,"") | P95: =IF(N95<>"",(1+$K$6)^-(N95),"") | Q95: =IFERROR(P95*O95,"")
F96: =IFERROR(IF(F95+1<$H$6,F95+1,""),"") | G96: =IF(F96<>"",G95+1,"") | H96: =IFERROR(VLOOKUP(G96,$B$3:$D$92,3,FALSE),"") | I96: =IF(F96<>"",1-H96,"") | J96: =IF(F96<>"",J95*I95,"") | K96: =IF(F96<>"",(1+$K$6)^-(1+F96),"") | N96: =IFERROR(IF(N95+1<$H$6,N95+1,""),"") | O96: =IF(N96<>"",O95*I95,"") | P96: =IF(N96<>"",(1+$K$6)^-(N96),"") | Q96: =IFERROR(P96*O96,"")
F97: =IFERROR(IF(F96+1<$H$6,F96+1,""),"") | G97: =IF(F97<>"",G96+1,"") | H97: =IFERROR(VLOOKUP(G97,$B$3:$D$92,3,FALSE),"") | I97: =IF(F97<>"",1-H97,"") | J97: =IF(F97<>"",J96*I96,"") | K97: =IF(F97<>"",(1+$K$6)^-(1+F97),"") | N97: =IFERROR(IF(N96+1<$H$6,N96+1,""),"") | O97: =IF(N97<>"",O96*I96,"") | P97: =IF(N97<>"",(1+$K$6)^-(N97),"") | Q97: =IFERROR(P97*O97,"")
F98: =IFERROR(IF(F97+1<$H$6,F97+1,""),"") | G98: =IF(F98<>"",G97+1,"") | H98: =IFERROR(VLOOKUP(G98,$B$3:$D$92,3,FALSE),"") | I98: =IF(F98<>"",1-H98,"") | J98: =IF(F98<>"",J97*I97,"") | K98: =IF(F98<>"",(1+$K$6)^-(1+F98),"") | N98: =IFERROR(IF(N97+1<$H$6,N97+1,""),"") | O98: =IF(N98<>"",O97*I97,"") | P98: =IF(N98<>"",(1+$K$6)^-(N98),"") | Q98: =IFERROR(P98*O98,"")
F99: =IFERROR(IF(F98+1<$H$6,F98+1,""),"") | G99: =IF(F99<>"",G98+1,"") | H99: =IFERROR(VLOOKUP(G99,$B$3:$D$92,3,FALSE),"") | I99: =IF(F99<>"",1-H99,"") | J99: =IF(F99<>"",J98*I98,"") | K99: =IF(F99<>"",(1+$K$6)^-(1+F99),"") | N99: =IFERROR(IF(N98+1<$H$6,N98+1,""),"") | O99: =IF(N99<>"",O98*I98,"") | P99: =IF(N99<>"",(1+$K$6)^-(N99),"") | Q99: =IFERROR(P99*O99,"")
F100: =IFERROR(IF(F99+1<$H$6,F99+1,""),"") | G100: =IF(F100<>"",G99+1,"") | H100: =IFERROR(VLOOKUP(G100,$B$3:$D$92,3,FALSE),"") | I100: =IF(F100<>"",1-H100,"") | J100: =IF(F100<>"",J99*I99,"") | K100: =IF(F100<>"",(1+$K$6)^-(1+F100),"") | N100: =IFERROR(IF(N99+1<$H$6,N99+1,""),"") | O100: =IF(N100<>"",O99*I99,"") | P100: =IF(N100<>"",(1+$K$6)^-(N100),"") | Q100: =IFERROR(P100*O100,"")
F101: =IFERROR(IF(F100+1<$H$6,F100+1,""),"") | G101: =IF(F101<>"",G100+1,"") | H101: =IFERROR(VLOOKUP(G101,$B$3:$D$92,3,FALSE),"") | I101: =IF(F101<>"",1-H101,"") | J101: =IF(F101<>"",J100*I100,"") | K101: =IF(F101<>"",(1+$K$6)^-(1+F101),"") | N101: =IFERROR(IF(N100+1<$H$6,N100+1,""),"") | O101: =IF(N101<>"",O100*I100,"") | P101: =IF(N101<>"",(1+$K$6)^-(N101),"") | Q101: =IFERROR(P101*O101,"")
F102: =IFERROR(IF(F101+1<$H$6,F101+1,""),"") | G102: =IF(F102<>"",G101+1,"") | H102: =IFERROR(VLOOKUP(G102,$B$3:$D$92,3,FALSE),"") | I102: =IF(F102<>"",1-H102,"") | J102: =IF(F102<>"",J101*I101,"") | K102: =IF(F102<>"",(1+$K$6)^-(1+F102),"") | N102: =IFERROR(IF(N101+1<$H$6,N101+1,""),"") | O102: =IF(N102<>"",O101*I101,"") | P102: =IF(N102<>"",(1+$K$6)^-(N102),"") | Q102: =IFERROR(P102*O102,"")
F103: =IFERROR(IF(F102+1<$H$6,F102+1,""),"") | G103: =IF(F103<>"",G102+1,"") | H103: =IFERROR(VLOOKUP(G103,$B$3:$D$92,3,FALSE),"") | I103: =IF(F103<>"",1-H103,"") | J103: =IF(F103<>"",J102*I102,"") | K103: =IF(F103<>"",(1+$K$6)^-(1+F103),"") | N103: =IFERROR(IF(N102+1<$H$6,N102+1,""),"") | O103: =IF(N103<>"",O102*I102,"") | P103: =IF(N103<>"",(1+$K$6)^-(N103),"") | Q103: =IFERROR(P103*O103,"")
F104: =IFERROR(IF(F103+1<$H$6,F103+1,""),"") | G104: =IF(F104<>"",G103+1,"") | H104: =IFERROR(VLOOKUP(G104,$B$3:$D$92,3,FALSE),"") | I104: =IF(F104<>"",1-H104,"") | J104: =IF(F104<>"",J103*I103,"") | K104: =IF(F104<>"",(1+$K$6)^-(1+F104),"") | N104: =IFERROR(IF(N103+1<$H$6,N103+1,""),"") | O104: =IF(N104<>"",O103*I103,"") | P104: =IF(N104<>"",(1+$K$6)^-(N104),"") | Q104: =IFERROR(P104*O104,"")
